2025-10-20T15:54:23.000000000Z [inf]  Starting Container
2025-10-20T15:54:23.987865258Z [err]  [2025-10-20 15:54:23 +0000] [1] [INFO] Starting gunicorn 21.2.0
2025-10-20T15:54:23.987870803Z [err]  [2025-10-20 15:54:23 +0000] [1] [INFO] Listening at: http://0.0.0.0:8080 (1)
2025-10-20T15:54:23.987875761Z [err]  [2025-10-20 15:54:23 +0000] [1] [INFO] Using worker: sync
2025-10-20T15:54:23.987882682Z [err]  [2025-10-20 15:54:23 +0000] [2] [INFO] Booting worker with pid: 2
2025-10-20T15:54:24.391556934Z [err]  2025-10-20 15:54:24.389556: I tensorflow/core/util/port.cc:113] oneDNN custom operations are on. You may see slightly different numerical results due to floating-point round-off errors from different computation orders. To turn them off, set the environment variable `TF_ENABLE_ONEDNN_OPTS=0`.
2025-10-20T15:54:24.397052181Z [err]  2025-10-20 15:54:24.392842: I external/local_tsl/tsl/cuda/cudart_stub.cc:31] Could not find cuda drivers on your machine, GPU will not be used.
2025-10-20T15:54:24.438598953Z [err]  2025-10-20 15:54:24.435212: E external/local_xla/xla/stream_executor/cuda/cuda_dnn.cc:9261] Unable to register cuDNN factory: Attempting to register factory for plugin cuDNN when one has already been registered
2025-10-20T15:54:24.438608761Z [err]  2025-10-20 15:54:24.435256: E external/local_xla/xla/stream_executor/cuda/cuda_fft.cc:607] Unable to register cuFFT factory: Attempting to register factory for plugin cuFFT when one has already been registered
2025-10-20T15:54:24.438615162Z [err]  2025-10-20 15:54:24.436945: E external/local_xla/xla/stream_executor/cuda/cuda_blas.cc:1515] Unable to register cuBLAS factory: Attempting to register factory for plugin cuBLAS when one has already been registered
2025-10-20T15:54:24.450295145Z [err]  2025-10-20 15:54:24.444707: I external/local_tsl/tsl/cuda/cudart_stub.cc:31] Could not find cuda drivers on your machine, GPU will not be used.
2025-10-20T15:54:24.450302308Z [err]  2025-10-20 15:54:24.444979: I tensorflow/core/platform/cpu_feature_guard.cc:182] This TensorFlow binary is optimized to use available CPU instructions in performance-critical operations.
2025-10-20T15:54:24.450309192Z [err]  To enable the following instructions: AVX2 AVX512F AVX512_VNNI AVX512_BF16 AVX_VNNI AMX_TILE AMX_INT8 AMX_BF16 FMA, in other operations, rebuild TensorFlow with the appropriate compiler flags.
2025-10-20T15:54:25.381216490Z [err]  2025-10-20 15:54:25.376288: W tensorflow/compiler/tf2tensorrt/utils/py_utils.cc:38] TF-TRT Warning: Could not find TensorRT
2025-10-20T15:54:26.341220728Z [err]  [2025-10-20 15:54:26 +0000] [2] [ERROR] Exception in worker process
2025-10-20T15:54:26.341233209Z [err]  Traceback (most recent call last):
2025-10-20T15:54:26.341241203Z [err]    File "/app/.venv/lib/python3.11/site-packages/keras/src/engine/base_layer.py", line 868, in from_config
2025-10-20T15:54:26.341247978Z [err]      return cls(**config)
2025-10-20T15:54:26.341255968Z [err]             ^^^^^^^^^^^^^
2025-10-20T15:54:26.341278751Z [err]    File "/app/.venv/lib/python3.11/site-packages/keras/src/utils/traceback_utils.py", line 70, in error_handler
2025-10-20T15:54:26.341288961Z [err]      raise e.with_traceback(filtered_tb) from None
2025-10-20T15:54:26.341295358Z [err]    File "/app/.venv/lib/python3.11/site-packages/keras/src/engine/input_layer.py", line 153, in __init__
2025-10-20T15:54:26.341303294Z [err]      raise ValueError(
2025-10-20T15:54:26.341310531Z [err]  ValueError: Unrecognized keyword arguments: ['batch_shape']
2025-10-20T15:54:26.341317923Z [err]
2025-10-20T15:54:26.341325982Z [err]  During handling of the above exception, another exception occurred:
2025-10-20T15:54:26.341333111Z [err]
2025-10-20T15:54:26.341339932Z [err]  Traceback (most recent call last):
2025-10-20T15:54:26.341347432Z [err]    File "/app/.venv/lib/python3.11/site-packages/gunicorn/arbiter.py", line 609, in spawn_worker
2025-10-20T15:54:26.341354667Z [err]      worker.init_process()
2025-10-20T15:54:26.341361938Z [err]    File "/app/.venv/lib/python3.11/site-packages/gunicorn/workers/base.py", line 134, in init_process
2025-10-20T15:54:26.341369663Z [err]      self.load_wsgi()
2025-10-20T15:54:26.341377605Z [err]    File "/app/.venv/lib/python3.11/site-packages/gunicorn/workers/base.py", line 146, in load_wsgi
2025-10-20T15:54:26.341385174Z [err]      self.wsgi = self.app.wsgi()
2025-10-20T15:54:26.341391384Z [err]                  ^^^^^^^^^^^^^^^
2025-10-20T15:54:26.341397943Z [err]    File "/app/.venv/lib/python3.11/site-packages/gunicorn/app/base.py", line 67, in wsgi
2025-10-20T15:54:26.341404332Z [err]      self.callable = self.load()
2025-10-20T15:54:26.341410410Z [err]                      ^^^^^^^^^^^
2025-10-20T15:54:26.341416717Z [err]    File "/app/.venv/lib/python3.11/site-packages/gunicorn/app/wsgiapp.py", line 58, in load
2025-10-20T15:54:26.341422915Z [err]      return self.load_wsgiapp()
2025-10-20T15:54:26.341429703Z [err]             ^^^^^^^^^^^^^^^^^^^
2025-10-20T15:54:26.341436189Z [err]    File "/app/.venv/lib/python3.11/site-packages/gunicorn/app/wsgiapp.py", line 48, in load_wsgiapp
2025-10-20T15:54:26.341442617Z [err]      return util.import_app(self.app_uri)
2025-10-20T15:54:26.341449548Z [err]             ^^^^^^^^^^^^^^^^^^^^^^^^^^^^^
2025-10-20T15:54:26.341455930Z [err]    File "/app/.venv/lib/python3.11/site-packages/gunicorn/util.py", line 371, in import_app
2025-10-20T15:54:26.341463091Z [err]      mod = importlib.import_module(module)
2025-10-20T15:54:26.341471034Z [err]            ^^^^^^^^^^^^^^^^^^^^^^^^^^^^^^^
2025-10-20T15:54:26.341477482Z [err]    File "/mise/installs/python/3.11.0/lib/python3.11/importlib/__init__.py", line 126, in import_module
2025-10-20T15:54:26.341484566Z [err]      return _bootstrap._gcd_import(name[level:], package, level)
2025-10-20T15:54:26.341491063Z [err]             ^^^^^^^^^^^^^^^^^^^^^^^^^^^^^^^^^^^^^^^^^^^^^^^^^^^^
2025-10-20T15:54:26.341497787Z [err]    File "<frozen importlib._bootstrap>", line 1206, in _gcd_import
2025-10-20T15:54:26.341503370Z [err]    File "<frozen importlib._bootstrap>", line 1178, in _find_and_load
2025-10-20T15:54:26.341510405Z [err]    File "<frozen importlib._bootstrap>", line 1149, in _find_and_load_unlocked
2025-10-20T15:54:26.341517799Z [err]    File "<frozen importlib._bootstrap>", line 690, in _load_unlocked
2025-10-20T15:54:26.341526907Z [err]    File "<frozen importlib._bootstrap_external>", line 940, in exec_module
2025-10-20T15:54:26.341534259Z [err]    File "<frozen importlib._bootstrap>", line 241, in _call_with_frames_removed
2025-10-20T15:54:26.341540724Z [err]    File "/app/api.py", line 19, in <module>
2025-10-20T15:54:26.341547998Z [err]      model = keras.models.load_model(model_path)
2025-10-20T15:54:26.341554525Z [err]              ^^^^^^^^^^^^^^^^^^^^^^^^^^^^^^^^^^^
2025-10-20T15:54:26.341560878Z [err]    File "/app/.venv/lib/python3.11/site-packages/keras/src/saving/saving_api.py", line 254, in load_model
2025-10-20T15:54:26.341568143Z [err]      return saving_lib.load_model(
2025-10-20T15:54:26.341574490Z [err]             ^^^^^^^^^^^^^^^^^^^^^^
2025-10-20T15:54:26.341581318Z [err]    File "/app/.venv/lib/python3.11/site-packages/keras/src/saving/saving_lib.py", line 281, in load_model
2025-10-20T15:54:26.341587513Z [err]      raise e
2025-10-20T15:54:26.341593931Z [err]    File "/app/.venv/lib/python3.11/site-packages/keras/src/saving/saving_lib.py", line 246, in load_model
2025-10-20T15:54:26.341599730Z [err]      model = deserialize_keras_object(
2025-10-20T15:54:26.341606177Z [err]              ^^^^^^^^^^^^^^^^^^^^^^^^^
2025-10-20T15:54:26.341611650Z [err]    File "/app/.venv/lib/python3.11/site-packages/keras/src/saving/serialization_lib.py", line 728, in deserialize_keras_object
2025-10-20T15:54:26.341618359Z [err]      instance = cls.from_config(inner_config)
2025-10-20T15:54:26.341624367Z [err]                 ^^^^^^^^^^^^^^^^^^^^^^^^^^^^^
2025-10-20T15:54:26.341631551Z [err]    File "/app/.venv/lib/python3.11/site-packages/keras/src/engine/sequential.py", line 466, in from_config
2025-10-20T15:54:26.341640539Z [err]      layer = layer_module.deserialize(
2025-10-20T15:54:26.341648489Z [err]              ^^^^^^^^^^^^^^^^^^^^^^^^^
2025-10-20T15:54:26.341656564Z [err]    File "/app/.venv/lib/python3.11/site-packages/keras/src/layers/serialization.py", line 276, in deserialize
2025-10-20T15:54:26.341664226Z [err]      return serialization_lib.deserialize_keras_object(
2025-10-20T15:54:26.341671272Z [err]             ^^^^^^^^^^^^^^^^^^^^^^^^^^^^^^^^^^^^^^^^^^^
2025-10-20T15:54:26.341677842Z [err]    File "/app/.venv/lib/python3.11/site-packages/keras/src/saving/serialization_lib.py", line 609, in deserialize_keras_object
2025-10-20T15:54:26.341684181Z [err]      return deserialize_keras_object(
2025-10-20T15:54:26.341690943Z [err]             ^^^^^^^^^^^^^^^^^^^^^^^^^
2025-10-20T15:54:26.341697103Z [err]    File "/app/.venv/lib/python3.11/site-packages/keras/src/saving/serialization_lib.py", line 728, in deserialize_keras_object
2025-10-20T15:54:26.341704362Z [err]      instance = cls.from_config(inner_config)
2025-10-20T15:54:26.341710776Z [err]                 ^^^^^^^^^^^^^^^^^^^^^^^^^^^^^
2025-10-20T15:54:26.341718332Z [err]    File "/app/.venv/lib/python3.11/site-packages/keras/src/engine/base_layer.py", line 870, in from_config
2025-10-20T15:54:26.341724594Z [err]      raise TypeError(
2025-10-20T15:54:26.341731456Z [err]  TypeError: Error when deserializing class 'InputLayer' using config={'batch_shape': [None, 128, 128, 3], 'dtype': 'float32', 'sparse': False, 'ragged': False, 'name': 'input_layer'}.
2025-10-20T15:54:26.341738317Z [err]
2025-10-20T15:54:26.341745442Z [err]  Exception encountered: Unrecognized keyword arguments: ['batch_shape']
2025-10-20T15:54:26.341752083Z [err]  [2025-10-20 15:54:26 +0000] [2] [INFO] Worker exiting (pid: 2)
2025-10-20T15:54:27.009472272Z [err]  [2025-10-20 15:54:26 +0000] [1] [ERROR] Worker (pid:2) exited with code 3
2025-10-20T15:54:27.009477688Z [err]  [2025-10-20 15:54:26 +0000] [1] [ERROR] Shutting down: Master
2025-10-20T15:54:27.009484513Z [err]  [2025-10-20 15:54:26 +0000] [1] [ERROR] Reason: Worker failed to boot.
2025-10-20T15:54:28.015371811Z [err]  [2025-10-20 15:54:27 +0000] [1] [INFO] Listening at: http://0.0.0.0:8080 (1)
2025-10-20T15:54:28.015384205Z [err]  [2025-10-20 15:54:27 +0000] [1] [INFO] Using worker: sync
2025-10-20T15:54:28.015392111Z [err]  [2025-10-20 15:54:27 +0000] [2] [INFO] Booting worker with pid: 2
2025-10-20T15:54:28.015500380Z [err]  [2025-10-20 15:54:27 +0000] [1] [INFO] Starting gunicorn 21.2.0
2025-10-20T15:54:28.678583203Z [err]  2025-10-20 15:54:28.676525: I tensorflow/core/util/port.cc:113] oneDNN custom operations are on. You may see slightly different numerical results due to floating-point round-off errors from different computation orders. To turn them off, set the environment variable `TF_ENABLE_ONEDNN_OPTS=0`.
2025-10-20T15:54:28.683163909Z [err]  2025-10-20 15:54:28.679385: I external/local_tsl/tsl/cuda/cudart_stub.cc:31] Could not find cuda drivers on your machine, GPU will not be used.
2025-10-20T15:54:28.726045917Z [err]  2025-10-20 15:54:28.720986: E external/local_xla/xla/stream_executor/cuda/cuda_dnn.cc:9261] Unable to register cuDNN factory: Attempting to register factory for plugin cuDNN when one has already been registered
2025-10-20T15:54:28.726054341Z [err]  2025-10-20 15:54:28.721038: E external/local_xla/xla/stream_executor/cuda/cuda_fft.cc:607] Unable to register cuFFT factory: Attempting to register factory for plugin cuFFT when one has already been registered
2025-10-20T15:54:28.726060099Z [err]  2025-10-20 15:54:28.722768: E external/local_xla/xla/stream_executor/cuda/cuda_blas.cc:1515] Unable to register cuBLAS factory: Attempting to register factory for plugin cuBLAS when one has already been registered
2025-10-20T15:54:28.732189733Z [err]  2025-10-20 15:54:28.730799: I external/local_tsl/tsl/cuda/cudart_stub.cc:31] Could not find cuda drivers on your machine, GPU will not be used.
2025-10-20T15:54:28.732197696Z [err]  2025-10-20 15:54:28.731093: I tensorflow/core/platform/cpu_feature_guard.cc:182] This TensorFlow binary is optimized to use available CPU instructions in performance-critical operations.
2025-10-20T15:54:28.732203125Z [err]  To enable the following instructions: AVX2 AVX512F AVX512_VNNI AVX512_BF16 AVX_VNNI AMX_TILE AMX_INT8 AMX_BF16 FMA, in other operations, rebuild TensorFlow with the appropriate compiler flags.
2025-10-20T15:54:29.675296250Z [err]  2025-10-20 15:54:29.667788: W tensorflow/compiler/tf2tensorrt/utils/py_utils.cc:38] TF-TRT Warning: Could not find TensorRT
2025-10-20T15:54:30.495282410Z [err]
2025-10-20T15:54:30.495294937Z [err]  Traceback (most recent call last):
2025-10-20T15:54:30.495303252Z [err]    File "/app/.venv/lib/python3.11/site-packages/gunicorn/arbiter.py", line 609, in spawn_worker
2025-10-20T15:54:30.495310283Z [err]      worker.init_process()
2025-10-20T15:54:30.495318305Z [err]    File "/app/.venv/lib/python3.11/site-packages/gunicorn/workers/base.py", line 134, in init_process
2025-10-20T15:54:30.495326352Z [err]      self.load_wsgi()
2025-10-20T15:54:30.495335448Z [err]    File "/app/.venv/lib/python3.11/site-packages/gunicorn/workers/base.py", line 146, in load_wsgi
2025-10-20T15:54:30.495344867Z [err]      self.wsgi = self.app.wsgi()
2025-10-20T15:54:30.495352060Z [err]                  ^^^^^^^^^^^^^^^
2025-10-20T15:54:30.495358734Z [err]    File "/app/.venv/lib/python3.11/site-packages/gunicorn/app/base.py", line 67, in wsgi
2025-10-20T15:54:30.495399456Z [err]  [2025-10-20 15:54:30 +0000] [2] [ERROR] Exception in worker process
2025-10-20T15:54:30.495405942Z [err]  Traceback (most recent call last):
2025-10-20T15:54:30.495412924Z [err]    File "/app/.venv/lib/python3.11/site-packages/keras/src/engine/base_layer.py", line 868, in from_config
2025-10-20T15:54:30.495419110Z [err]      return cls(**config)
2025-10-20T15:54:30.495424858Z [err]             ^^^^^^^^^^^^^
2025-10-20T15:54:30.495431022Z [err]    File "/app/.venv/lib/python3.11/site-packages/keras/src/utils/traceback_utils.py", line 70, in error_handler
2025-10-20T15:54:30.495437632Z [err]      raise e.with_traceback(filtered_tb) from None
2025-10-20T15:54:30.495444372Z [err]    File "/app/.venv/lib/python3.11/site-packages/keras/src/engine/input_layer.py", line 153, in __init__
2025-10-20T15:54:30.495450834Z [err]      raise ValueError(
2025-10-20T15:54:30.495457520Z [err]  ValueError: Unrecognized keyword arguments: ['batch_shape']
2025-10-20T15:54:30.495463523Z [err]
2025-10-20T15:54:30.495470173Z [err]  During handling of the above exception, another exception occurred:
2025-10-20T15:54:30.495801673Z [err]      self.callable = self.load()
2025-10-20T15:54:30.495808778Z [err]             ^^^^^^^^^^^^^^^^^^^^^^^^^^^^^
2025-10-20T15:54:30.495810725Z [err]                      ^^^^^^^^^^^
2025-10-20T15:54:30.495816303Z [err]    File "/app/.venv/lib/python3.11/site-packages/gunicorn/util.py", line 371, in import_app
2025-10-20T15:54:30.495818977Z [err]    File "/app/.venv/lib/python3.11/site-packages/gunicorn/app/wsgiapp.py", line 58, in load
2025-10-20T15:54:30.495820657Z [err]    File "<frozen importlib._bootstrap>", line 241, in _call_with_frames_removed
2025-10-20T15:54:30.495823487Z [err]      mod = importlib.import_module(module)
2025-10-20T15:54:30.495826435Z [err]      return self.load_wsgiapp()
2025-10-20T15:54:30.495829852Z [err]            ^^^^^^^^^^^^^^^^^^^^^^^^^^^^^^^
2025-10-20T15:54:30.495834696Z [err]             ^^^^^^^^^^^^^^^^^^^
2025-10-20T15:54:30.495836432Z [err]    File "/mise/installs/python/3.11.0/lib/python3.11/importlib/__init__.py", line 126, in import_module
2025-10-20T15:54:30.495841995Z [err]      return _bootstrap._gcd_import(name[level:], package, level)
2025-10-20T15:54:30.495842856Z [err]    File "/app/.venv/lib/python3.11/site-packages/gunicorn/app/wsgiapp.py", line 48, in load_wsgiapp
2025-10-20T15:54:30.495848638Z [err]      return util.import_app(self.app_uri)
2025-10-20T15:54:30.495852110Z [err]             ^^^^^^^^^^^^^^^^^^^^^^^^^^^^^^^^^^^^^^^^^^^^^^^^^^^^
2025-10-20T15:54:30.495857650Z [err]    File "<frozen importlib._bootstrap>", line 1206, in _gcd_import
2025-10-20T15:54:30.495862050Z [err]    File "<frozen importlib._bootstrap>", line 1178, in _find_and_load
2025-10-20T15:54:30.495866668Z [err]    File "<frozen importlib._bootstrap>", line 1149, in _find_and_load_unlocked
2025-10-20T15:54:30.495871069Z [err]    File "<frozen importlib._bootstrap>", line 690, in _load_unlocked
2025-10-20T15:54:30.495877445Z [err]    File "<frozen importlib._bootstrap_external>", line 940, in exec_module
2025-10-20T15:54:30.496885977Z [err]    File "/app/api.py", line 19, in <module>
2025-10-20T15:54:30.496889886Z [err]      instance = cls.from_config(inner_config)
2025-10-20T15:54:30.496891995Z [err]    File "/app/.venv/lib/python3.11/site-packages/keras/src/layers/serialization.py", line 276, in deserialize
2025-10-20T15:54:30.496896888Z [err]      model = keras.models.load_model(model_path)
2025-10-20T15:54:30.496898174Z [err]                 ^^^^^^^^^^^^^^^^^^^^^^^^^^^^^
2025-10-20T15:54:30.496900819Z [err]      return serialization_lib.deserialize_keras_object(
2025-10-20T15:54:30.496905881Z [err]              ^^^^^^^^^^^^^^^^^^^^^^^^^^^^^^^^^^^
2025-10-20T15:54:30.496906577Z [err]    File "/app/.venv/lib/python3.11/site-packages/keras/src/engine/sequential.py", line 466, in from_config
2025-10-20T15:54:30.496909448Z [err]             ^^^^^^^^^^^^^^^^^^^^^^^^^^^^^^^^^^^^^^^^^^^
2025-10-20T15:54:30.496914668Z [err]      layer = layer_module.deserialize(
2025-10-20T15:54:30.496915094Z [err]    File "/app/.venv/lib/python3.11/site-packages/keras/src/saving/saving_api.py", line 254, in load_model
2025-10-20T15:54:30.496921277Z [err]              ^^^^^^^^^^^^^^^^^^^^^^^^^
2025-10-20T15:54:30.496922231Z [err]      return saving_lib.load_model(
2025-10-20T15:54:30.496931489Z [err]             ^^^^^^^^^^^^^^^^^^^^^^
2025-10-20T15:54:30.496941540Z [err]    File "/app/.venv/lib/python3.11/site-packages/keras/src/saving/saving_lib.py", line 281, in load_model
2025-10-20T15:54:30.496953868Z [err]      raise e
2025-10-20T15:54:30.496960347Z [err]    File "/app/.venv/lib/python3.11/site-packages/keras/src/saving/saving_lib.py", line 246, in load_model
2025-10-20T15:54:30.496965270Z [err]      model = deserialize_keras_object(
2025-10-20T15:54:30.496974578Z [err]              ^^^^^^^^^^^^^^^^^^^^^^^^^
2025-10-20T15:54:30.496979075Z [err]    File "/app/.venv/lib/python3.11/site-packages/keras/src/saving/serialization_lib.py", line 728, in deserialize_keras_object
2025-10-20T15:54:30.497822334Z [err]    File "/app/.venv/lib/python3.11/site-packages/keras/src/saving/serialization_lib.py", line 609, in deserialize_keras_object
2025-10-20T15:54:30.497827258Z [err]      return deserialize_keras_object(
2025-10-20T15:54:30.497832284Z [err]             ^^^^^^^^^^^^^^^^^^^^^^^^^
2025-10-20T15:54:30.497837347Z [err]    File "/app/.venv/lib/python3.11/site-packages/keras/src/saving/serialization_lib.py", line 728, in deserialize_keras_object
2025-10-20T15:54:30.497841974Z [err]      instance = cls.from_config(inner_config)
2025-10-20T15:54:30.497847067Z [err]                 ^^^^^^^^^^^^^^^^^^^^^^^^^^^^^
2025-10-20T15:54:30.497851392Z [err]    File "/app/.venv/lib/python3.11/site-packages/keras/src/engine/base_layer.py", line 870, in from_config
2025-10-20T15:54:30.497855291Z [err]      raise TypeError(
2025-10-20T15:54:30.497859564Z [err]  TypeError: Error when deserializing class 'InputLayer' using config={'batch_shape': [None, 128, 128, 3], 'dtype': 'float32', 'sparse': False, 'ragged': False, 'name': 'input_layer'}.
2025-10-20T15:54:30.497865951Z [err]
2025-10-20T15:54:30.497871442Z [err]  Exception encountered: Unrecognized keyword arguments: ['batch_shape']
2025-10-20T15:54:30.497875780Z [err]  [2025-10-20 15:54:30 +0000] [2] [INFO] Worker exiting (pid: 2)
2025-10-20T15:54:31.178720524Z [err]  [2025-10-20 15:54:31 +0000] [1] [ERROR] Worker (pid:2) exited with code 3
2025-10-20T15:54:31.178727295Z [err]  [2025-10-20 15:54:31 +0000] [1] [ERROR] Shutting down: Master
2025-10-20T15:54:31.178733780Z [err]  [2025-10-20 15:54:31 +0000] [1] [ERROR] Reason: Worker failed to boot.
2025-10-20T15:54:32.207923958Z [err]  [2025-10-20 15:54:32 +0000] [1] [INFO] Starting gunicorn 21.2.0
2025-10-20T15:54:32.207937686Z [err]  [2025-10-20 15:54:32 +0000] [1] [INFO] Listening at: http://0.0.0.0:8080 (1)
2025-10-20T15:54:32.207944832Z [err]  [2025-10-20 15:54:32 +0000] [1] [INFO] Using worker: sync
2025-10-20T15:54:32.209001189Z [err]  [2025-10-20 15:54:32 +0000] [2] [INFO] Booting worker with pid: 2
2025-10-20T15:54:33.028866932Z [err]  2025-10-20 15:54:32.922018: E external/local_xla/xla/stream_executor/cuda/cuda_dnn.cc:9261] Unable to register cuDNN factory: Attempting to register factory for plugin cuDNN when one has already been registered
2025-10-20T15:54:33.028877201Z [err]  2025-10-20 15:54:32.922066: E external/local_xla/xla/stream_executor/cuda/cuda_fft.cc:607] Unable to register cuFFT factory: Attempting to register factory for plugin cuFFT when one has already been registered
2025-10-20T15:54:33.028883616Z [err]  2025-10-20 15:54:32.924354: E external/local_xla/xla/stream_executor/cuda/cuda_blas.cc:1515] Unable to register cuBLAS factory: Attempting to register factory for plugin cuBLAS when one has already been registered
2025-10-20T15:54:33.028888124Z [err]  2025-10-20 15:54:32.934878: I external/local_tsl/tsl/cuda/cudart_stub.cc:31] Could not find cuda drivers on your machine, GPU will not be used.
2025-10-20T15:54:33.028893330Z [err]  2025-10-20 15:54:32.935171: I tensorflow/core/platform/cpu_feature_guard.cc:182] This TensorFlow binary is optimized to use available CPU instructions in performance-critical operations.
2025-10-20T15:54:33.029062418Z [err]  2025-10-20 15:54:32.878811: I tensorflow/core/util/port.cc:113] oneDNN custom operations are on. You may see slightly different numerical results due to floating-point round-off errors from different computation orders. To turn them off, set the environment variable `TF_ENABLE_ONEDNN_OPTS=0`.
2025-10-20T15:54:33.029066588Z [err]  2025-10-20 15:54:32.881749: I external/local_tsl/tsl/cuda/cudart_stub.cc:31] Could not find cuda drivers on your machine, GPU will not be used.
2025-10-20T15:54:33.029274003Z [err]  To enable the following instructions: AVX2 AVX512F AVX512_VNNI AVX512_BF16 AVX_VNNI AMX_TILE AMX_INT8 AMX_BF16 FMA, in other operations, rebuild TensorFlow with the appropriate compiler flags.
2025-10-20T15:54:34.014646106Z [err]  2025-10-20 15:54:33.840979: W tensorflow/compiler/tf2tensorrt/utils/py_utils.cc:38] TF-TRT Warning: Could not find TensorRT
2025-10-20T15:54:34.689379210Z [err]  [2025-10-20 15:54:34 +0000] [2] [ERROR] Exception in worker process
2025-10-20T15:54:34.689384850Z [err]      self.load_wsgi()
2025-10-20T15:54:34.689388081Z [err]  Traceback (most recent call last):
2025-10-20T15:54:34.689393831Z [err]    File "/app/.venv/lib/python3.11/site-packages/keras/src/engine/base_layer.py", line 868, in from_config
2025-10-20T15:54:34.689396521Z [err]    File "/app/.venv/lib/python3.11/site-packages/gunicorn/workers/base.py", line 146, in load_wsgi
2025-10-20T15:54:34.689399766Z [err]      return cls(**config)
2025-10-20T15:54:34.689403842Z [err]      self.wsgi = self.app.wsgi()
2025-10-20T15:54:34.689409761Z [err]             ^^^^^^^^^^^^^
2025-10-20T15:54:34.689413461Z [err]                  ^^^^^^^^^^^^^^^
2025-10-20T15:54:34.689415824Z [err]    File "/app/.venv/lib/python3.11/site-packages/keras/src/utils/traceback_utils.py", line 70, in error_handler
2025-10-20T15:54:34.689419901Z [err]    File "/app/.venv/lib/python3.11/site-packages/gunicorn/app/base.py", line 67, in wsgi
2025-10-20T15:54:34.689422474Z [err]      raise e.with_traceback(filtered_tb) from None
2025-10-20T15:54:34.689426845Z [err]    File "/app/.venv/lib/python3.11/site-packages/keras/src/engine/input_layer.py", line 153, in __init__
2025-10-20T15:54:34.689431264Z [err]      raise ValueError(
2025-10-20T15:54:34.689435369Z [err]  ValueError: Unrecognized keyword arguments: ['batch_shape']
2025-10-20T15:54:34.689440506Z [err]
2025-10-20T15:54:34.689446611Z [err]  During handling of the above exception, another exception occurred:
2025-10-20T15:54:34.689452448Z [err]
2025-10-20T15:54:34.689457854Z [err]  Traceback (most recent call last):
2025-10-20T15:54:34.689463621Z [err]    File "/app/.venv/lib/python3.11/site-packages/gunicorn/arbiter.py", line 609, in spawn_worker
2025-10-20T15:54:34.689471001Z [err]      worker.init_process()
2025-10-20T15:54:34.689477266Z [err]    File "/app/.venv/lib/python3.11/site-packages/gunicorn/workers/base.py", line 134, in init_process
2025-10-20T15:54:34.690059728Z [err]      self.callable = self.load()
2025-10-20T15:54:34.690062104Z [err]    File "<frozen importlib._bootstrap>", line 1149, in _find_and_load_unlocked
2025-10-20T15:54:34.690067647Z [err]                      ^^^^^^^^^^^
2025-10-20T15:54:34.690073492Z [err]    File "/app/.venv/lib/python3.11/site-packages/gunicorn/app/wsgiapp.py", line 58, in load
2025-10-20T15:54:34.690074591Z [err]    File "<frozen importlib._bootstrap>", line 690, in _load_unlocked
2025-10-20T15:54:34.690079195Z [err]      return self.load_wsgiapp()
2025-10-20T15:54:34.690083817Z [err]    File "<frozen importlib._bootstrap_external>", line 940, in exec_module
2025-10-20T15:54:34.690084502Z [err]             ^^^^^^^^^^^^^^^^^^^
2025-10-20T15:54:34.690091452Z [err]    File "<frozen importlib._bootstrap>", line 241, in _call_with_frames_removed
2025-10-20T15:54:34.690092401Z [err]    File "/app/.venv/lib/python3.11/site-packages/gunicorn/app/wsgiapp.py", line 48, in load_wsgiapp
2025-10-20T15:54:34.690097777Z [err]      return util.import_app(self.app_uri)
2025-10-20T15:54:34.690102728Z [err]             ^^^^^^^^^^^^^^^^^^^^^^^^^^^^^
2025-10-20T15:54:34.690107557Z [err]    File "/app/.venv/lib/python3.11/site-packages/gunicorn/util.py", line 371, in import_app
2025-10-20T15:54:34.690111351Z [err]      mod = importlib.import_module(module)
2025-10-20T15:54:34.690116202Z [err]            ^^^^^^^^^^^^^^^^^^^^^^^^^^^^^^^
2025-10-20T15:54:34.690121399Z [err]    File "/mise/installs/python/3.11.0/lib/python3.11/importlib/__init__.py", line 126, in import_module
2025-10-20T15:54:34.690126165Z [err]      return _bootstrap._gcd_import(name[level:], package, level)
2025-10-20T15:54:34.690130335Z [err]             ^^^^^^^^^^^^^^^^^^^^^^^^^^^^^^^^^^^^^^^^^^^^^^^^^^^^
2025-10-20T15:54:34.690134123Z [err]    File "<frozen importlib._bootstrap>", line 1206, in _gcd_import
2025-10-20T15:54:34.690138173Z [err]    File "<frozen importlib._bootstrap>", line 1178, in _find_and_load
2025-10-20T15:54:34.691463933Z [err]    File "/app/api.py", line 19, in <module>
2025-10-20T15:54:34.691466576Z [err]      return serialization_lib.deserialize_keras_object(
2025-10-20T15:54:34.691473874Z [err]             ^^^^^^^^^^^^^^^^^^^^^^^^^^^^^^^^^^^^^^^^^^^
2025-10-20T15:54:34.691474851Z [err]      model = keras.models.load_model(model_path)
2025-10-20T15:54:34.691474924Z [err]                 ^^^^^^^^^^^^^^^^^^^^^^^^^^^^^
2025-10-20T15:54:34.691481882Z [err]              ^^^^^^^^^^^^^^^^^^^^^^^^^^^^^^^^^^^
2025-10-20T15:54:34.691482857Z [err]    File "/app/.venv/lib/python3.11/site-packages/keras/src/saving/saving_lib.py", line 246, in load_model
2025-10-20T15:54:34.691484757Z [err]              ^^^^^^^^^^^^^^^^^^^^^^^^^
2025-10-20T15:54:34.691486447Z [err]    File "/app/.venv/lib/python3.11/site-packages/keras/src/engine/sequential.py", line 466, in from_config
2025-10-20T15:54:34.691493020Z [err]    File "/app/.venv/lib/python3.11/site-packages/keras/src/layers/serialization.py", line 276, in deserialize
2025-10-20T15:54:34.691494904Z [err]      model = deserialize_keras_object(
2025-10-20T15:54:34.691496676Z [err]      layer = layer_module.deserialize(
2025-10-20T15:54:34.691500995Z [err]              ^^^^^^^^^^^^^^^^^^^^^^^^^
2025-10-20T15:54:34.691503076Z [err]    File "/app/.venv/lib/python3.11/site-packages/keras/src/saving/saving_api.py", line 254, in load_model
2025-10-20T15:54:34.691510688Z [err]      return saving_lib.load_model(
2025-10-20T15:54:34.691514090Z [err]    File "/app/.venv/lib/python3.11/site-packages/keras/src/saving/serialization_lib.py", line 728, in deserialize_keras_object
2025-10-20T15:54:34.691518508Z [err]             ^^^^^^^^^^^^^^^^^^^^^^
2025-10-20T15:54:34.691523514Z [err]      instance = cls.from_config(inner_config)
2025-10-20T15:54:34.691527454Z [err]    File "/app/.venv/lib/python3.11/site-packages/keras/src/saving/saving_lib.py", line 281, in load_model
2025-10-20T15:54:34.691533577Z [err]      raise e
2025-10-20T15:54:34.692445450Z [err]  Exception encountered: Unrecognized keyword arguments: ['batch_shape']
2025-10-20T15:54:34.692453050Z [err]  [2025-10-20 15:54:34 +0000] [2] [INFO] Worker exiting (pid: 2)
2025-10-20T15:54:34.692461646Z [err]    File "/app/.venv/lib/python3.11/site-packages/keras/src/saving/serialization_lib.py", line 609, in deserialize_keras_object
2025-10-20T15:54:34.692469194Z [err]      return deserialize_keras_object(
2025-10-20T15:54:34.692474717Z [err]             ^^^^^^^^^^^^^^^^^^^^^^^^^
2025-10-20T15:54:34.692482076Z [err]    File "/app/.venv/lib/python3.11/site-packages/keras/src/saving/serialization_lib.py", line 728, in deserialize_keras_object
2025-10-20T15:54:34.692488047Z [err]      instance = cls.from_config(inner_config)
2025-10-20T15:54:34.692493686Z [err]                 ^^^^^^^^^^^^^^^^^^^^^^^^^^^^^
2025-10-20T15:54:34.692499331Z [err]    File "/app/.venv/lib/python3.11/site-packages/keras/src/engine/base_layer.py", line 870, in from_config
2025-10-20T15:54:34.692504740Z [err]      raise TypeError(
2025-10-20T15:54:34.692509908Z [err]  TypeError: Error when deserializing class 'InputLayer' using config={'batch_shape': [None, 128, 128, 3], 'dtype': 'float32', 'sparse': False, 'ragged': False, 'name': 'input_layer'}.
2025-10-20T15:54:34.692514767Z [err]
2025-10-20T15:54:35.349347481Z [err]  [2025-10-20 15:54:35 +0000] [1] [ERROR] Worker (pid:2) exited with code 3
2025-10-20T15:54:35.349354758Z [err]  [2025-10-20 15:54:35 +0000] [1] [ERROR] Shutting down: Master
2025-10-20T15:54:35.349359676Z [err]  [2025-10-20 15:54:35 +0000] [1] [ERROR] Reason: Worker failed to boot.
2025-10-20T15:54:36.373336136Z [err]  [2025-10-20 15:54:36 +0000] [1] [INFO] Starting gunicorn 21.2.0
2025-10-20T15:54:36.373346412Z [err]  [2025-10-20 15:54:36 +0000] [1] [INFO] Listening at: http://0.0.0.0:8080 (1)
2025-10-20T15:54:36.373352136Z [err]  [2025-10-20 15:54:36 +0000] [1] [INFO] Using worker: sync
2025-10-20T15:54:36.374346532Z [err]  [2025-10-20 15:54:36 +0000] [2] [INFO] Booting worker with pid: 2
2025-10-20T15:54:37.074422402Z [err]  2025-10-20 15:54:37.054744: I tensorflow/core/util/port.cc:113] oneDNN custom operations are on. You may see slightly different numerical results due to floating-point round-off errors from different computation orders. To turn them off, set the environment variable `TF_ENABLE_ONEDNN_OPTS=0`.
2025-10-20T15:54:37.074431749Z [err]  2025-10-20 15:54:37.057941: I external/local_tsl/tsl/cuda/cudart_stub.cc:31] Could not find cuda drivers on your machine, GPU will not be used.
2025-10-20T15:54:37.107254962Z [err]  2025-10-20 15:54:37.101063: E external/local_xla/xla/stream_executor/cuda/cuda_dnn.cc:9261] Unable to register cuDNN factory: Attempting to register factory for plugin cuDNN when one has already been registered
2025-10-20T15:54:37.107263602Z [err]  2025-10-20 15:54:37.101117: E external/local_xla/xla/stream_executor/cuda/cuda_fft.cc:607] Unable to register cuFFT factory: Attempting to register factory for plugin cuFFT when one has already been registered
2025-10-20T15:54:37.107269897Z [err]  2025-10-20 15:54:37.103356: E external/local_xla/xla/stream_executor/cuda/cuda_blas.cc:1515] Unable to register cuBLAS factory: Attempting to register factory for plugin cuBLAS when one has already been registered
2025-10-20T15:54:37.112928544Z [err]  2025-10-20 15:54:37.112362: I external/local_tsl/tsl/cuda/cudart_stub.cc:31] Could not find cuda drivers on your machine, GPU will not be used.
2025-10-20T15:54:37.114112344Z [err]  2025-10-20 15:54:37.112624: I tensorflow/core/platform/cpu_feature_guard.cc:182] This TensorFlow binary is optimized to use available CPU instructions in performance-critical operations.
2025-10-20T15:54:37.114119755Z [err]  To enable the following instructions: AVX2 AVX512F AVX512_VNNI AVX512_BF16 AVX_VNNI AMX_TILE AMX_INT8 AMX_BF16 FMA, in other operations, rebuild TensorFlow with the appropriate compiler flags.
2025-10-20T15:54:38.134775786Z [err]  2025-10-20 15:54:38.077231: W tensorflow/compiler/tf2tensorrt/utils/py_utils.cc:38] TF-TRT Warning: Could not find TensorRT
2025-10-20T15:54:39.122294140Z [err]  [2025-10-20 15:54:38 +0000] [2] [ERROR] Exception in worker process
2025-10-20T15:54:39.122302620Z [err]  Traceback (most recent call last):
2025-10-20T15:54:39.122308108Z [err]    File "/app/.venv/lib/python3.11/site-packages/keras/src/engine/base_layer.py", line 868, in from_config
2025-10-20T15:54:39.122313129Z [err]      return cls(**config)
2025-10-20T15:54:39.122318433Z [err]             ^^^^^^^^^^^^^
2025-10-20T15:54:39.122326738Z [err]    File "/app/.venv/lib/python3.11/site-packages/keras/src/utils/traceback_utils.py", line 70, in error_handler
2025-10-20T15:54:39.122332255Z [err]      raise e.with_traceback(filtered_tb) from None
2025-10-20T15:54:39.122337653Z [err]    File "/app/.venv/lib/python3.11/site-packages/keras/src/engine/input_layer.py", line 153, in __init__
2025-10-20T15:54:39.122510482Z [err]      raise ValueError(
2025-10-20T15:54:39.122517447Z [err]  ValueError: Unrecognized keyword arguments: ['batch_shape']
2025-10-20T15:54:39.122523391Z [err]
2025-10-20T15:54:39.122529361Z [err]  During handling of the above exception, another exception occurred:
2025-10-20T15:54:39.122541944Z [err]
2025-10-20T15:54:39.122547154Z [err]  Traceback (most recent call last):
2025-10-20T15:54:39.122552055Z [err]    File "/app/.venv/lib/python3.11/site-packages/gunicorn/arbiter.py", line 609, in spawn_worker
2025-10-20T15:54:39.122557810Z [err]      worker.init_process()
2025-10-20T15:54:39.122562941Z [err]    File "/app/.venv/lib/python3.11/site-packages/gunicorn/workers/base.py", line 134, in init_process
2025-10-20T15:54:39.122567649Z [err]      self.load_wsgi()
2025-10-20T15:54:39.122572425Z [err]    File "/app/.venv/lib/python3.11/site-packages/gunicorn/workers/base.py", line 146, in load_wsgi
2025-10-20T15:54:39.122578680Z [err]      self.wsgi = self.app.wsgi()
2025-10-20T15:54:39.122583975Z [err]                  ^^^^^^^^^^^^^^^
2025-10-20T15:54:39.122589152Z [err]    File "/app/.venv/lib/python3.11/site-packages/gunicorn/app/base.py", line 67, in wsgi
2025-10-20T15:54:39.123894836Z [err]             ^^^^^^^^^^^^^^^^^^^^^^^^^^^^^^^^^^^^^^^^^^^^^^^^^^^^
2025-10-20T15:54:39.123907881Z [err]      self.callable = self.load()
2025-10-20T15:54:39.123909992Z [err]    File "<frozen importlib._bootstrap>", line 1206, in _gcd_import
2025-10-20T15:54:39.123923228Z [err]                      ^^^^^^^^^^^
2025-10-20T15:54:39.123923663Z [err]    File "<frozen importlib._bootstrap>", line 1178, in _find_and_load
2025-10-20T15:54:39.123937968Z [err]    File "/app/.venv/lib/python3.11/site-packages/gunicorn/app/wsgiapp.py", line 58, in load
2025-10-20T15:54:39.123938412Z [err]    File "<frozen importlib._bootstrap>", line 1149, in _find_and_load_unlocked
2025-10-20T15:54:39.123950697Z [err]      return self.load_wsgiapp()
2025-10-20T15:54:39.123954624Z [err]    File "<frozen importlib._bootstrap>", line 690, in _load_unlocked
2025-10-20T15:54:39.123966072Z [err]    File "<frozen importlib._bootstrap_external>", line 940, in exec_module
2025-10-20T15:54:39.123966387Z [err]             ^^^^^^^^^^^^^^^^^^^
2025-10-20T15:54:39.123978972Z [err]    File "<frozen importlib._bootstrap>", line 241, in _call_with_frames_removed
2025-10-20T15:54:39.123981375Z [err]    File "/app/.venv/lib/python3.11/site-packages/gunicorn/app/wsgiapp.py", line 48, in load_wsgiapp
2025-10-20T15:54:39.123989317Z [err]      return util.import_app(self.app_uri)
2025-10-20T15:54:39.123995895Z [err]             ^^^^^^^^^^^^^^^^^^^^^^^^^^^^^
2025-10-20T15:54:39.124003128Z [err]    File "/app/.venv/lib/python3.11/site-packages/gunicorn/util.py", line 371, in import_app
2025-10-20T15:54:39.124009276Z [err]      mod = importlib.import_module(module)
2025-10-20T15:54:39.124014462Z [err]            ^^^^^^^^^^^^^^^^^^^^^^^^^^^^^^^
2025-10-20T15:54:39.124019653Z [err]    File "/mise/installs/python/3.11.0/lib/python3.11/importlib/__init__.py", line 126, in import_module
2025-10-20T15:54:39.124025517Z [err]      return _bootstrap._gcd_import(name[level:], package, level)
2025-10-20T15:54:39.124945590Z [err]    File "/app/api.py", line 19, in <module>
2025-10-20T15:54:39.124946303Z [err]                 ^^^^^^^^^^^^^^^^^^^^^^^^^^^^^
2025-10-20T15:54:39.124964747Z [err]      model = keras.models.load_model(model_path)
2025-10-20T15:54:39.124964857Z [err]    File "/app/.venv/lib/python3.11/site-packages/keras/src/engine/sequential.py", line 466, in from_config
2025-10-20T15:54:39.124978329Z [err]              ^^^^^^^^^^^^^^^^^^^^^^^^^^^^^^^^^^^
2025-10-20T15:54:39.124981927Z [err]      layer = layer_module.deserialize(
2025-10-20T15:54:39.124989937Z [err]    File "/app/.venv/lib/python3.11/site-packages/keras/src/saving/saving_api.py", line 254, in load_model
2025-10-20T15:54:39.124995559Z [err]              ^^^^^^^^^^^^^^^^^^^^^^^^^
2025-10-20T15:54:39.125007183Z [err]      return saving_lib.load_model(
2025-10-20T15:54:39.125011720Z [err]    File "/app/.venv/lib/python3.11/site-packages/keras/src/layers/serialization.py", line 276, in deserialize
2025-10-20T15:54:39.125017436Z [err]             ^^^^^^^^^^^^^^^^^^^^^^
2025-10-20T15:54:39.125027520Z [err]      return serialization_lib.deserialize_keras_object(
2025-10-20T15:54:39.125031301Z [err]    File "/app/.venv/lib/python3.11/site-packages/keras/src/saving/saving_lib.py", line 281, in load_model
2025-10-20T15:54:39.125044936Z [err]      raise e
2025-10-20T15:54:39.125047154Z [err]             ^^^^^^^^^^^^^^^^^^^^^^^^^^^^^^^^^^^^^^^^^^^
2025-10-20T15:54:39.125054936Z [err]    File "/app/.venv/lib/python3.11/site-packages/keras/src/saving/saving_lib.py", line 246, in load_model
2025-10-20T15:54:39.125061783Z [err]      model = deserialize_keras_object(
2025-10-20T15:54:39.125068640Z [err]              ^^^^^^^^^^^^^^^^^^^^^^^^^
2025-10-20T15:54:39.125076725Z [err]    File "/app/.venv/lib/python3.11/site-packages/keras/src/saving/serialization_lib.py", line 728, in deserialize_keras_object
2025-10-20T15:54:39.125084378Z [err]      instance = cls.from_config(inner_config)
2025-10-20T15:54:39.126053427Z [err]    File "/app/.venv/lib/python3.11/site-packages/keras/src/saving/serialization_lib.py", line 609, in deserialize_keras_object
2025-10-20T15:54:39.126062231Z [err]      return deserialize_keras_object(
2025-10-20T15:54:39.126069794Z [err]             ^^^^^^^^^^^^^^^^^^^^^^^^^
2025-10-20T15:54:39.126076813Z [err]    File "/app/.venv/lib/python3.11/site-packages/keras/src/saving/serialization_lib.py", line 728, in deserialize_keras_object
2025-10-20T15:54:39.126084180Z [err]      instance = cls.from_config(inner_config)
2025-10-20T15:54:39.126090254Z [err]                 ^^^^^^^^^^^^^^^^^^^^^^^^^^^^^
2025-10-20T15:54:39.126096360Z [err]    File "/app/.venv/lib/python3.11/site-packages/keras/src/engine/base_layer.py", line 870, in from_config
2025-10-20T15:54:39.126102461Z [err]      raise TypeError(
2025-10-20T15:54:39.126108972Z [err]  TypeError: Error when deserializing class 'InputLayer' using config={'batch_shape': [None, 128, 128, 3], 'dtype': 'float32', 'sparse': False, 'ragged': False, 'name': 'input_layer'}.
2025-10-20T15:54:39.126115319Z [err]
2025-10-20T15:54:39.126121830Z [err]  Exception encountered: Unrecognized keyword arguments: ['batch_shape']
2025-10-20T15:54:39.126127871Z [err]  [2025-10-20 15:54:38 +0000] [2] [INFO] Worker exiting (pid: 2)
2025-10-20T15:54:39.513576304Z [err]  [2025-10-20 15:54:39 +0000] [1] [ERROR] Worker (pid:2) exited with code 3
2025-10-20T15:54:39.514747998Z [err]  [2025-10-20 15:54:39 +0000] [1] [ERROR] Shutting down: Master
2025-10-20T15:54:39.514754932Z [err]  [2025-10-20 15:54:39 +0000] [1] [ERROR] Reason: Worker failed to boot.
2025-10-20T15:54:40.548460810Z [err]  [2025-10-20 15:54:40 +0000] [1] [INFO] Starting gunicorn 21.2.0
2025-10-20T15:54:40.548466906Z [err]  [2025-10-20 15:54:40 +0000] [1] [INFO] Listening at: http://0.0.0.0:8080 (1)
2025-10-20T15:54:40.548473771Z [err]  [2025-10-20 15:54:40 +0000] [1] [INFO] Using worker: sync
2025-10-20T15:54:40.548480405Z [err]  [2025-10-20 15:54:40 +0000] [2] [INFO] Booting worker with pid: 2
2025-10-20T15:54:41.225261916Z [err]  2025-10-20 15:54:41.221863: I tensorflow/core/util/port.cc:113] oneDNN custom operations are on. You may see slightly different numerical results due to floating-point round-off errors from different computation orders. To turn them off, set the environment variable `TF_ENABLE_ONEDNN_OPTS=0`.
2025-10-20T15:54:41.225940203Z [err]  2025-10-20 15:54:41.225236: I external/local_tsl/tsl/cuda/cudart_stub.cc:31] Could not find cuda drivers on your machine, GPU will not be used.
2025-10-20T15:54:41.302305425Z [err]  2025-10-20 15:54:41.270237: E external/local_xla/xla/stream_executor/cuda/cuda_dnn.cc:9261] Unable to register cuDNN factory: Attempting to register factory for plugin cuDNN when one has already been registered
2025-10-20T15:54:41.302312360Z [err]  2025-10-20 15:54:41.270282: E external/local_xla/xla/stream_executor/cuda/cuda_fft.cc:607] Unable to register cuFFT factory: Attempting to register factory for plugin cuFFT when one has already been registered
2025-10-20T15:54:41.302319249Z [err]  2025-10-20 15:54:41.272540: E external/local_xla/xla/stream_executor/cuda/cuda_blas.cc:1515] Unable to register cuBLAS factory: Attempting to register factory for plugin cuBLAS when one has already been registered
2025-10-20T15:54:41.302325612Z [err]  2025-10-20 15:54:41.280660: I external/local_tsl/tsl/cuda/cudart_stub.cc:31] Could not find cuda drivers on your machine, GPU will not be used.
2025-10-20T15:54:41.302332225Z [err]  2025-10-20 15:54:41.280929: I tensorflow/core/platform/cpu_feature_guard.cc:182] This TensorFlow binary is optimized to use available CPU instructions in performance-critical operations.
2025-10-20T15:54:41.302341288Z [err]  To enable the following instructions: AVX2 AVX512F AVX512_VNNI AVX512_BF16 AVX_VNNI AMX_TILE AMX_INT8 AMX_BF16 FMA, in other operations, rebuild TensorFlow with the appropriate compiler flags.
2025-10-20T15:54:42.224973201Z [err]  2025-10-20 15:54:42.219258: W tensorflow/compiler/tf2tensorrt/utils/py_utils.cc:38] TF-TRT Warning: Could not find TensorRT
2025-10-20T15:54:43.212224169Z [err]
2025-10-20T15:54:43.212231905Z [err]                  ^^^^^^^^^^^^^^^
2025-10-20T15:54:43.212233216Z [err]  Traceback (most recent call last):
2025-10-20T15:54:43.212240227Z [err]    File "/app/.venv/lib/python3.11/site-packages/gunicorn/arbiter.py", line 609, in spawn_worker
2025-10-20T15:54:43.212246501Z [err]    File "/app/.venv/lib/python3.11/site-packages/gunicorn/app/base.py", line 67, in wsgi
2025-10-20T15:54:43.212248559Z [err]      worker.init_process()
2025-10-20T15:54:43.212255198Z [err]    File "/app/.venv/lib/python3.11/site-packages/gunicorn/workers/base.py", line 134, in init_process
2025-10-20T15:54:43.212261548Z [err]      self.load_wsgi()
2025-10-20T15:54:43.212266987Z [err]    File "/app/.venv/lib/python3.11/site-packages/gunicorn/workers/base.py", line 146, in load_wsgi
2025-10-20T15:54:43.212272937Z [err]      self.wsgi = self.app.wsgi()
2025-10-20T15:54:43.212345012Z [err]  [2025-10-20 15:54:43 +0000] [2] [ERROR] Exception in worker process
2025-10-20T15:54:43.212350290Z [err]  Traceback (most recent call last):
2025-10-20T15:54:43.212354749Z [err]    File "/app/.venv/lib/python3.11/site-packages/keras/src/engine/base_layer.py", line 868, in from_config
2025-10-20T15:54:43.212361085Z [err]      return cls(**config)
2025-10-20T15:54:43.212365432Z [err]             ^^^^^^^^^^^^^
2025-10-20T15:54:43.212369686Z [err]    File "/app/.venv/lib/python3.11/site-packages/keras/src/utils/traceback_utils.py", line 70, in error_handler
2025-10-20T15:54:43.212374696Z [err]      raise e.with_traceback(filtered_tb) from None
2025-10-20T15:54:43.212379898Z [err]    File "/app/.venv/lib/python3.11/site-packages/keras/src/engine/input_layer.py", line 153, in __init__
2025-10-20T15:54:43.212384688Z [err]      raise ValueError(
2025-10-20T15:54:43.212388950Z [err]  ValueError: Unrecognized keyword arguments: ['batch_shape']
2025-10-20T15:54:43.212396718Z [err]
2025-10-20T15:54:43.212402558Z [err]  During handling of the above exception, another exception occurred:
2025-10-20T15:54:43.214267115Z [err]      self.callable = self.load()
2025-10-20T15:54:43.214274836Z [err]                      ^^^^^^^^^^^
2025-10-20T15:54:43.214280581Z [err]    File "/app/.venv/lib/python3.11/site-packages/gunicorn/app/wsgiapp.py", line 58, in load
2025-10-20T15:54:43.214286282Z [err]      return self.load_wsgiapp()
2025-10-20T15:54:43.214291516Z [err]             ^^^^^^^^^^^^^^^^^^^
2025-10-20T15:54:43.214297281Z [err]    File "/app/.venv/lib/python3.11/site-packages/gunicorn/app/wsgiapp.py", line 48, in load_wsgiapp
2025-10-20T15:54:43.214302849Z [err]      return util.import_app(self.app_uri)
2025-10-20T15:54:43.214308103Z [err]             ^^^^^^^^^^^^^^^^^^^^^^^^^^^^^
2025-10-20T15:54:43.214313537Z [err]    File "/app/.venv/lib/python3.11/site-packages/gunicorn/util.py", line 371, in import_app
2025-10-20T15:54:43.214321191Z [err]      mod = importlib.import_module(module)
2025-10-20T15:54:43.214326466Z [err]            ^^^^^^^^^^^^^^^^^^^^^^^^^^^^^^^
2025-10-20T15:54:43.214331610Z [err]    File "/mise/installs/python/3.11.0/lib/python3.11/importlib/__init__.py", line 126, in import_module
2025-10-20T15:54:43.214339758Z [err]  [2025-10-20 15:54:43 +0000] [2] [INFO] Worker exiting (pid: 2)
2025-10-20T15:54:43.214340685Z [err]    File "/app/.venv/lib/python3.11/site-packages/keras/src/saving/serialization_lib.py", line 609, in deserialize_keras_object
2025-10-20T15:54:43.214349795Z [err]      return deserialize_keras_object(
2025-10-20T15:54:43.214356372Z [err]      raise TypeError(
2025-10-20T15:54:43.214357629Z [err]             ^^^^^^^^^^^^^^^^^^^^^^^^^
2025-10-20T15:54:43.214357631Z [err]    File "/app/.venv/lib/python3.11/site-packages/keras/src/saving/serialization_lib.py", line 728, in deserialize_keras_object
2025-10-20T15:54:43.214365384Z [err]      instance = cls.from_config(inner_config)
2025-10-20T15:54:43.214366400Z [err]  TypeError: Error when deserializing class 'InputLayer' using config={'batch_shape': [None, 128, 128, 3], 'dtype': 'float32', 'sparse': False, 'ragged': False, 'name': 'input_layer'}.
2025-10-20T15:54:43.214372014Z [err]                 ^^^^^^^^^^^^^^^^^^^^^^^^^^^^^
2025-10-20T15:54:43.214378398Z [err]    File "/app/.venv/lib/python3.11/site-packages/keras/src/engine/base_layer.py", line 870, in from_config
2025-10-20T15:54:43.214378635Z [err]
2025-10-20T15:54:43.214385906Z [err]  Exception encountered: Unrecognized keyword arguments: ['batch_shape']
2025-10-20T15:54:43.214394161Z [err]      return _bootstrap._gcd_import(name[level:], package, level)
2025-10-20T15:54:43.214399586Z [err]             ^^^^^^^^^^^^^^^^^^^^^^^^^^^^^^^^^^^^^^^^^^^^^^^^^^^^
2025-10-20T15:54:43.214404547Z [err]    File "<frozen importlib._bootstrap>", line 1206, in _gcd_import
2025-10-20T15:54:43.214409577Z [err]    File "<frozen importlib._bootstrap>", line 1178, in _find_and_load
2025-10-20T15:54:43.214421251Z [err]    File "<frozen importlib._bootstrap>", line 1149, in _find_and_load_unlocked
2025-10-20T15:54:43.214427296Z [err]    File "<frozen importlib._bootstrap>", line 690, in _load_unlocked
2025-10-20T15:54:43.214432971Z [err]    File "<frozen importlib._bootstrap_external>", line 940, in exec_module
2025-10-20T15:54:43.214438530Z [err]    File "<frozen importlib._bootstrap>", line 241, in _call_with_frames_removed
2025-10-20T15:54:43.214445392Z [err]    File "/app/api.py", line 19, in <module>
2025-10-20T15:54:43.214451072Z [err]      model = keras.models.load_model(model_path)
2025-10-20T15:54:43.214465655Z [err]              ^^^^^^^^^^^^^^^^^^^^^^^^^^^^^^^^^^^
2025-10-20T15:54:43.214472408Z [err]    File "/app/.venv/lib/python3.11/site-packages/keras/src/saving/saving_api.py", line 254, in load_model
2025-10-20T15:54:43.214477089Z [err]      return saving_lib.load_model(
2025-10-20T15:54:43.214482012Z [err]             ^^^^^^^^^^^^^^^^^^^^^^
2025-10-20T15:54:43.214486996Z [err]    File "/app/.venv/lib/python3.11/site-packages/keras/src/saving/saving_lib.py", line 281, in load_model
2025-10-20T15:54:43.214492035Z [err]      raise e
2025-10-20T15:54:43.214497355Z [err]    File "/app/.venv/lib/python3.11/site-packages/keras/src/saving/saving_lib.py", line 246, in load_model
2025-10-20T15:54:43.214503012Z [err]      model = deserialize_keras_object(
2025-10-20T15:54:43.214509131Z [err]              ^^^^^^^^^^^^^^^^^^^^^^^^^
2025-10-20T15:54:43.214517377Z [err]    File "/app/.venv/lib/python3.11/site-packages/keras/src/saving/serialization_lib.py", line 728, in deserialize_keras_object
2025-10-20T15:54:43.214521962Z [err]      instance = cls.from_config(inner_config)
2025-10-20T15:54:43.214527075Z [err]                 ^^^^^^^^^^^^^^^^^^^^^^^^^^^^^
2025-10-20T15:54:43.214531712Z [err]    File "/app/.venv/lib/python3.11/site-packages/keras/src/engine/sequential.py", line 466, in from_config
2025-10-20T15:54:43.214536693Z [err]      layer = layer_module.deserialize(
2025-10-20T15:54:43.214547931Z [err]              ^^^^^^^^^^^^^^^^^^^^^^^^^
2025-10-20T15:54:43.214554404Z [err]    File "/app/.venv/lib/python3.11/site-packages/keras/src/layers/serialization.py", line 276, in deserialize
2025-10-20T15:54:43.214559016Z [err]      return serialization_lib.deserialize_keras_object(
2025-10-20T15:54:43.214563852Z [err]             ^^^^^^^^^^^^^^^^^^^^^^^^^^^^^^^^^^^^^^^^^^^
2025-10-20T15:54:44.236898771Z [err]  [2025-10-20 15:54:44 +0000] [1] [ERROR] Worker (pid:2) exited with code 3
2025-10-20T15:54:44.236908052Z [err]  [2025-10-20 15:54:44 +0000] [1] [ERROR] Shutting down: Master
2025-10-20T15:54:44.236917029Z [err]  [2025-10-20 15:54:44 +0000] [1] [ERROR] Reason: Worker failed to boot.
2025-10-20T15:54:45.284177435Z [err]  [2025-10-20 15:54:45 +0000] [1] [INFO] Starting gunicorn 21.2.0
2025-10-20T15:54:45.284183707Z [err]  [2025-10-20 15:54:45 +0000] [1] [INFO] Listening at: http://0.0.0.0:8080 (1)
2025-10-20T15:54:45.284189137Z [err]  [2025-10-20 15:54:45 +0000] [1] [INFO] Using worker: sync
2025-10-20T15:54:45.284195178Z [err]  [2025-10-20 15:54:45 +0000] [2] [INFO] Booting worker with pid: 2
2025-10-20T15:54:45.786045881Z [err]  2025-10-20 15:54:45.780515: I tensorflow/core/util/port.cc:113] oneDNN custom operations are on. You may see slightly different numerical results due to floating-point round-off errors from different computation orders. To turn them off, set the environment variable `TF_ENABLE_ONEDNN_OPTS=0`.
2025-10-20T15:54:45.786053494Z [err]  2025-10-20 15:54:45.783313: I external/local_tsl/tsl/cuda/cudart_stub.cc:31] Could not find cuda drivers on your machine, GPU will not be used.
2025-10-20T15:54:45.828513601Z [err]  2025-10-20 15:54:45.824846: E external/local_xla/xla/stream_executor/cuda/cuda_dnn.cc:9261] Unable to register cuDNN factory: Attempting to register factory for plugin cuDNN when one has already been registered
2025-10-20T15:54:45.828523631Z [err]  2025-10-20 15:54:45.824891: E external/local_xla/xla/stream_executor/cuda/cuda_fft.cc:607] Unable to register cuFFT factory: Attempting to register factory for plugin cuFFT when one has already been registered
2025-10-20T15:54:45.828529069Z [err]  2025-10-20 15:54:45.826697: E external/local_xla/xla/stream_executor/cuda/cuda_blas.cc:1515] Unable to register cuBLAS factory: Attempting to register factory for plugin cuBLAS when one has already been registered
2025-10-20T15:54:45.841644386Z [err]  2025-10-20 15:54:45.834872: I external/local_tsl/tsl/cuda/cudart_stub.cc:31] Could not find cuda drivers on your machine, GPU will not be used.
2025-10-20T15:54:45.841651804Z [err]  2025-10-20 15:54:45.835163: I tensorflow/core/platform/cpu_feature_guard.cc:182] This TensorFlow binary is optimized to use available CPU instructions in performance-critical operations.
2025-10-20T15:54:45.841658291Z [err]  To enable the following instructions: AVX2 AVX512F AVX512_VNNI AVX512_BF16 AVX_VNNI AMX_TILE AMX_INT8 AMX_BF16 FMA, in other operations, rebuild TensorFlow with the appropriate compiler flags.
2025-10-20T15:54:46.885865207Z [err]  2025-10-20 15:54:46.871751: W tensorflow/compiler/tf2tensorrt/utils/py_utils.cc:38] TF-TRT Warning: Could not find TensorRT
2025-10-20T15:54:47.780745773Z [err]    File "/app/.venv/lib/python3.11/site-packages/gunicorn/app/base.py", line 67, in wsgi
2025-10-20T15:54:47.780775651Z [err]  [2025-10-20 15:54:47 +0000] [2] [ERROR] Exception in worker process
2025-10-20T15:54:47.780782870Z [err]  Traceback (most recent call last):
2025-10-20T15:54:47.780790504Z [err]    File "/app/.venv/lib/python3.11/site-packages/keras/src/engine/base_layer.py", line 868, in from_config
2025-10-20T15:54:47.780796559Z [err]      return cls(**config)
2025-10-20T15:54:47.780801830Z [err]             ^^^^^^^^^^^^^
2025-10-20T15:54:47.780809521Z [err]    File "/app/.venv/lib/python3.11/site-packages/keras/src/utils/traceback_utils.py", line 70, in error_handler
2025-10-20T15:54:47.780819367Z [err]      raise e.with_traceback(filtered_tb) from None
2025-10-20T15:54:47.780825526Z [err]    File "/app/.venv/lib/python3.11/site-packages/keras/src/engine/input_layer.py", line 153, in __init__
2025-10-20T15:54:47.780831628Z [err]      raise ValueError(
2025-10-20T15:54:47.780839717Z [err]  ValueError: Unrecognized keyword arguments: ['batch_shape']
2025-10-20T15:54:47.780845754Z [err]
2025-10-20T15:54:47.780851295Z [err]  During handling of the above exception, another exception occurred:
2025-10-20T15:54:47.780860050Z [err]
2025-10-20T15:54:47.780866893Z [err]  Traceback (most recent call last):
2025-10-20T15:54:47.780874152Z [err]    File "/app/.venv/lib/python3.11/site-packages/gunicorn/arbiter.py", line 609, in spawn_worker
2025-10-20T15:54:47.780881460Z [err]      worker.init_process()
2025-10-20T15:54:47.780886466Z [err]    File "/app/.venv/lib/python3.11/site-packages/gunicorn/workers/base.py", line 134, in init_process
2025-10-20T15:54:47.780892978Z [err]      self.load_wsgi()
2025-10-20T15:54:47.780899144Z [err]    File "/app/.venv/lib/python3.11/site-packages/gunicorn/workers/base.py", line 146, in load_wsgi
2025-10-20T15:54:47.780905464Z [err]      self.wsgi = self.app.wsgi()
2025-10-20T15:54:47.780911151Z [err]                  ^^^^^^^^^^^^^^^
2025-10-20T15:54:47.782105171Z [err]      self.callable = self.load()
2025-10-20T15:54:47.782115076Z [err]                      ^^^^^^^^^^^
2025-10-20T15:54:47.782117475Z [err]            ^^^^^^^^^^^^^^^^^^^^^^^^^^^^^^^
2025-10-20T15:54:47.782122147Z [err]    File "/app/.venv/lib/python3.11/site-packages/gunicorn/app/wsgiapp.py", line 58, in load
2025-10-20T15:54:47.782128398Z [err]      return self.load_wsgiapp()
2025-10-20T15:54:47.782133626Z [err]    File "/mise/installs/python/3.11.0/lib/python3.11/importlib/__init__.py", line 126, in import_module
2025-10-20T15:54:47.782136786Z [err]             ^^^^^^^^^^^^^^^^^^^
2025-10-20T15:54:47.782142951Z [err]      return _bootstrap._gcd_import(name[level:], package, level)
2025-10-20T15:54:47.782143975Z [err]    File "/app/.venv/lib/python3.11/site-packages/gunicorn/app/wsgiapp.py", line 48, in load_wsgiapp
2025-10-20T15:54:47.782150687Z [err]      return util.import_app(self.app_uri)
2025-10-20T15:54:47.782151641Z [err]             ^^^^^^^^^^^^^^^^^^^^^^^^^^^^^^^^^^^^^^^^^^^^^^^^^^^^
2025-10-20T15:54:47.782157754Z [err]             ^^^^^^^^^^^^^^^^^^^^^^^^^^^^^
2025-10-20T15:54:47.782160844Z [err]    File "<frozen importlib._bootstrap>", line 1206, in _gcd_import
2025-10-20T15:54:47.782164986Z [err]    File "/app/.venv/lib/python3.11/site-packages/gunicorn/util.py", line 371, in import_app
2025-10-20T15:54:47.782169733Z [err]    File "<frozen importlib._bootstrap>", line 1178, in _find_and_load
2025-10-20T15:54:47.782172623Z [err]      mod = importlib.import_module(module)
2025-10-20T15:54:47.782178708Z [err]    File "<frozen importlib._bootstrap>", line 1149, in _find_and_load_unlocked
2025-10-20T15:54:47.782185879Z [err]    File "<frozen importlib._bootstrap>", line 690, in _load_unlocked
2025-10-20T15:54:47.782194089Z [err]    File "<frozen importlib._bootstrap_external>", line 940, in exec_module
2025-10-20T15:54:47.782200804Z [err]    File "<frozen importlib._bootstrap>", line 241, in _call_with_frames_removed
2025-10-20T15:54:47.782766611Z [err]    File "/app/api.py", line 19, in <module>
2025-10-20T15:54:47.782773412Z [err]    File "/app/.venv/lib/python3.11/site-packages/keras/src/saving/saving_lib.py", line 246, in load_model
2025-10-20T15:54:47.782774956Z [err]      model = keras.models.load_model(model_path)
2025-10-20T15:54:47.782784676Z [err]              ^^^^^^^^^^^^^^^^^^^^^^^^^^^^^^^^^^^
2025-10-20T15:54:47.782785841Z [err]      model = deserialize_keras_object(
2025-10-20T15:54:47.782791724Z [err]    File "/app/.venv/lib/python3.11/site-packages/keras/src/saving/saving_api.py", line 254, in load_model
2025-10-20T15:54:47.782795155Z [err]              ^^^^^^^^^^^^^^^^^^^^^^^^^
2025-10-20T15:54:47.782799350Z [err]      return saving_lib.load_model(
2025-10-20T15:54:47.782803011Z [err]    File "/app/.venv/lib/python3.11/site-packages/keras/src/saving/serialization_lib.py", line 728, in deserialize_keras_object
2025-10-20T15:54:47.782807282Z [err]             ^^^^^^^^^^^^^^^^^^^^^^
2025-10-20T15:54:47.782811197Z [err]      instance = cls.from_config(inner_config)
2025-10-20T15:54:47.782814035Z [err]    File "/app/.venv/lib/python3.11/site-packages/keras/src/saving/saving_lib.py", line 281, in load_model
2025-10-20T15:54:47.782819815Z [err]                 ^^^^^^^^^^^^^^^^^^^^^^^^^^^^^
2025-10-20T15:54:47.782821116Z [err]      raise e
2025-10-20T15:54:47.782826967Z [err]    File "/app/.venv/lib/python3.11/site-packages/keras/src/engine/sequential.py", line 466, in from_config
2025-10-20T15:54:47.782838967Z [err]      layer = layer_module.deserialize(
2025-10-20T15:54:47.782846726Z [err]              ^^^^^^^^^^^^^^^^^^^^^^^^^
2025-10-20T15:54:47.782856255Z [err]    File "/app/.venv/lib/python3.11/site-packages/keras/src/layers/serialization.py", line 276, in deserialize
2025-10-20T15:54:47.782863255Z [err]      return serialization_lib.deserialize_keras_object(
2025-10-20T15:54:47.782871181Z [err]             ^^^^^^^^^^^^^^^^^^^^^^^^^^^^^^^^^^^^^^^^^^^
2025-10-20T15:54:47.783171246Z [err]    File "/app/.venv/lib/python3.11/site-packages/keras/src/saving/serialization_lib.py", line 609, in deserialize_keras_object
2025-10-20T15:54:47.783171537Z [err]      raise TypeError(
2025-10-20T15:54:47.783180161Z [err]  TypeError: Error when deserializing class 'InputLayer' using config={'batch_shape': [None, 128, 128, 3], 'dtype': 'float32', 'sparse': False, 'ragged': False, 'name': 'input_layer'}.
2025-10-20T15:54:47.783180212Z [err]      return deserialize_keras_object(
2025-10-20T15:54:47.783187567Z [err]
2025-10-20T15:54:47.783187782Z [err]             ^^^^^^^^^^^^^^^^^^^^^^^^^
2025-10-20T15:54:47.783195757Z [err]  Exception encountered: Unrecognized keyword arguments: ['batch_shape']
2025-10-20T15:54:47.783195982Z [err]    File "/app/.venv/lib/python3.11/site-packages/keras/src/saving/serialization_lib.py", line 728, in deserialize_keras_object
2025-10-20T15:54:47.783201995Z [err]  [2025-10-20 15:54:47 +0000] [2] [INFO] Worker exiting (pid: 2)
2025-10-20T15:54:47.783205736Z [err]      instance = cls.from_config(inner_config)
2025-10-20T15:54:47.783211031Z [err]                 ^^^^^^^^^^^^^^^^^^^^^^^^^^^^^
2025-10-20T15:54:47.783215913Z [err]    File "/app/.venv/lib/python3.11/site-packages/keras/src/engine/base_layer.py", line 870, in from_config
2025-10-20T15:54:48.476918270Z [err]  [2025-10-20 15:54:48 +0000] [1] [ERROR] Worker (pid:2) exited with code 3
2025-10-20T15:54:48.476927078Z [err]  [2025-10-20 15:54:48 +0000] [1] [ERROR] Shutting down: Master
2025-10-20T15:54:48.476933550Z [err]  [2025-10-20 15:54:48 +0000] [1] [ERROR] Reason: Worker failed to boot.
2025-10-20T15:54:49.640915976Z [err]  [2025-10-20 15:54:49 +0000] [1] [INFO] Starting gunicorn 21.2.0
2025-10-20T15:54:49.640928640Z [err]  [2025-10-20 15:54:49 +0000] [1] [INFO] Listening at: http://0.0.0.0:8080 (1)
2025-10-20T15:54:49.640934710Z [err]  [2025-10-20 15:54:49 +0000] [1] [INFO] Using worker: sync
2025-10-20T15:54:49.646966872Z [err]  [2025-10-20 15:54:49 +0000] [2] [INFO] Booting worker with pid: 2
2025-10-20T15:54:50.260337125Z [err]  2025-10-20 15:54:50.253216: I tensorflow/core/util/port.cc:113] oneDNN custom operations are on. You may see slightly different numerical results due to floating-point round-off errors from different computation orders. To turn them off, set the environment variable `TF_ENABLE_ONEDNN_OPTS=0`.
2025-10-20T15:54:50.260345488Z [err]  2025-10-20 15:54:50.255926: I external/local_tsl/tsl/cuda/cudart_stub.cc:31] Could not find cuda drivers on your machine, GPU will not be used.
2025-10-20T15:54:50.302613295Z [err]  2025-10-20 15:54:50.296929: E external/local_xla/xla/stream_executor/cuda/cuda_dnn.cc:9261] Unable to register cuDNN factory: Attempting to register factory for plugin cuDNN when one has already been registered
2025-10-20T15:54:50.302619616Z [err]  2025-10-20 15:54:50.296972: E external/local_xla/xla/stream_executor/cuda/cuda_fft.cc:607] Unable to register cuFFT factory: Attempting to register factory for plugin cuFFT when one has already been registered
2025-10-20T15:54:50.302625625Z [err]  2025-10-20 15:54:50.298722: E external/local_xla/xla/stream_executor/cuda/cuda_blas.cc:1515] Unable to register cuBLAS factory: Attempting to register factory for plugin cuBLAS when one has already been registered
2025-10-20T15:54:50.308762226Z [err]  2025-10-20 15:54:50.306266: I external/local_tsl/tsl/cuda/cudart_stub.cc:31] Could not find cuda drivers on your machine, GPU will not be used.
2025-10-20T15:54:50.308770247Z [err]  2025-10-20 15:54:50.306541: I tensorflow/core/platform/cpu_feature_guard.cc:182] This TensorFlow binary is optimized to use available CPU instructions in performance-critical operations.
2025-10-20T15:54:50.308778082Z [err]  To enable the following instructions: AVX2 AVX512F AVX512_VNNI AVX512_BF16 AVX_VNNI AMX_TILE AMX_INT8 AMX_BF16 FMA, in other operations, rebuild TensorFlow with the appropriate compiler flags.
2025-10-20T15:54:51.219389130Z [err]  2025-10-20 15:54:51.190386: W tensorflow/compiler/tf2tensorrt/utils/py_utils.cc:38] TF-TRT Warning: Could not find TensorRT
2025-10-20T15:54:52.248473039Z [err]    File "/app/.venv/lib/python3.11/site-packages/keras/src/engine/input_layer.py", line 153, in __init__
2025-10-20T15:54:52.248483447Z [err]      raise ValueError(
2025-10-20T15:54:52.248489560Z [err]  ValueError: Unrecognized keyword arguments: ['batch_shape']
2025-10-20T15:54:52.248496223Z [err]
2025-10-20T15:54:52.248504098Z [err]  During handling of the above exception, another exception occurred:
2025-10-20T15:54:52.248510203Z [err]
2025-10-20T15:54:52.248515870Z [err]  Traceback (most recent call last):
2025-10-20T15:54:52.248521278Z [err]    File "/app/.venv/lib/python3.11/site-packages/gunicorn/arbiter.py", line 609, in spawn_worker
2025-10-20T15:54:52.248526631Z [err]      worker.init_process()
2025-10-20T15:54:52.248532498Z [err]    File "/app/.venv/lib/python3.11/site-packages/gunicorn/workers/base.py", line 134, in init_process
2025-10-20T15:54:52.248538823Z [err]      self.load_wsgi()
2025-10-20T15:54:52.248545079Z [err]  [2025-10-20 15:54:52 +0000] [2] [ERROR] Exception in worker process
2025-10-20T15:54:52.248545673Z [err]    File "/app/.venv/lib/python3.11/site-packages/gunicorn/workers/base.py", line 146, in load_wsgi
2025-10-20T15:54:52.248552641Z [err]      self.wsgi = self.app.wsgi()
2025-10-20T15:54:52.248554490Z [err]  Traceback (most recent call last):
2025-10-20T15:54:52.248562021Z [err]                  ^^^^^^^^^^^^^^^
2025-10-20T15:54:52.248563949Z [err]    File "/app/.venv/lib/python3.11/site-packages/keras/src/engine/base_layer.py", line 868, in from_config
2025-10-20T15:54:52.248568893Z [err]    File "/app/.venv/lib/python3.11/site-packages/gunicorn/app/base.py", line 67, in wsgi
2025-10-20T15:54:52.248571807Z [err]      return cls(**config)
2025-10-20T15:54:52.248578108Z [err]             ^^^^^^^^^^^^^
2025-10-20T15:54:52.248585113Z [err]    File "/app/.venv/lib/python3.11/site-packages/keras/src/utils/traceback_utils.py", line 70, in error_handler
2025-10-20T15:54:52.248591787Z [err]      raise e.with_traceback(filtered_tb) from None
2025-10-20T15:54:52.249324012Z [err]      self.callable = self.load()
2025-10-20T15:54:52.249329507Z [err]                      ^^^^^^^^^^^
2025-10-20T15:54:52.249334564Z [err]    File "/app/.venv/lib/python3.11/site-packages/gunicorn/app/wsgiapp.py", line 58, in load
2025-10-20T15:54:52.249341236Z [err]      return self.load_wsgiapp()
2025-10-20T15:54:52.249345307Z [err]             ^^^^^^^^^^^^^^^^^^^
2025-10-20T15:54:52.249351822Z [err]    File "/app/.venv/lib/python3.11/site-packages/gunicorn/app/wsgiapp.py", line 48, in load_wsgiapp
2025-10-20T15:54:52.249356270Z [err]      return util.import_app(self.app_uri)
2025-10-20T15:54:52.249361364Z [err]             ^^^^^^^^^^^^^^^^^^^^^^^^^^^^^
2025-10-20T15:54:52.249365997Z [err]    File "/app/.venv/lib/python3.11/site-packages/gunicorn/util.py", line 371, in import_app
2025-10-20T15:54:52.249370313Z [err]      mod = importlib.import_module(module)
2025-10-20T15:54:52.249374346Z [err]            ^^^^^^^^^^^^^^^^^^^^^^^^^^^^^^^
2025-10-20T15:54:52.249379005Z [err]    File "/mise/installs/python/3.11.0/lib/python3.11/importlib/__init__.py", line 126, in import_module
2025-10-20T15:54:52.249383896Z [err]      return _bootstrap._gcd_import(name[level:], package, level)
2025-10-20T15:54:52.249387955Z [err]             ^^^^^^^^^^^^^^^^^^^^^^^^^^^^^^^^^^^^^^^^^^^^^^^^^^^^
2025-10-20T15:54:52.249392241Z [err]    File "<frozen importlib._bootstrap>", line 1206, in _gcd_import
2025-10-20T15:54:52.249396321Z [err]    File "<frozen importlib._bootstrap>", line 1178, in _find_and_load
2025-10-20T15:54:52.249401766Z [err]    File "<frozen importlib._bootstrap>", line 1149, in _find_and_load_unlocked
2025-10-20T15:54:52.249406615Z [err]    File "<frozen importlib._bootstrap>", line 690, in _load_unlocked
2025-10-20T15:54:52.249410467Z [err]    File "<frozen importlib._bootstrap_external>", line 940, in exec_module
2025-10-20T15:54:52.249414418Z [err]    File "<frozen importlib._bootstrap>", line 241, in _call_with_frames_removed
2025-10-20T15:54:52.250883571Z [err]    File "/app/api.py", line 19, in <module>
2025-10-20T15:54:52.250890878Z [err]      model = keras.models.load_model(model_path)
2025-10-20T15:54:52.250895543Z [err]              ^^^^^^^^^^^^^^^^^^^^^^^^^^^^^^^^^^^
2025-10-20T15:54:52.250900341Z [err]    File "/app/.venv/lib/python3.11/site-packages/keras/src/saving/saving_api.py", line 254, in load_model
2025-10-20T15:54:52.250905124Z [err]      return saving_lib.load_model(
2025-10-20T15:54:52.250909356Z [err]             ^^^^^^^^^^^^^^^^^^^^^^
2025-10-20T15:54:52.250992545Z [err]    File "/app/.venv/lib/python3.11/site-packages/keras/src/saving/saving_lib.py", line 281, in load_model
2025-10-20T15:54:52.250998488Z [err]      raise e
2025-10-20T15:54:52.251004815Z [err]    File "/app/.venv/lib/python3.11/site-packages/keras/src/saving/saving_lib.py", line 246, in load_model
2025-10-20T15:54:52.251010795Z [err]      model = deserialize_keras_object(
2025-10-20T15:54:52.251015805Z [err]              ^^^^^^^^^^^^^^^^^^^^^^^^^
2025-10-20T15:54:52.251020591Z [err]    File "/app/.venv/lib/python3.11/site-packages/keras/src/saving/serialization_lib.py", line 728, in deserialize_keras_object
2025-10-20T15:54:52.251027213Z [err]      instance = cls.from_config(inner_config)
2025-10-20T15:54:52.251032401Z [err]                 ^^^^^^^^^^^^^^^^^^^^^^^^^^^^^
2025-10-20T15:54:52.251037099Z [err]    File "/app/.venv/lib/python3.11/site-packages/keras/src/engine/sequential.py", line 466, in from_config
2025-10-20T15:54:52.251041437Z [err]      layer = layer_module.deserialize(
2025-10-20T15:54:52.251046189Z [err]              ^^^^^^^^^^^^^^^^^^^^^^^^^
2025-10-20T15:54:52.251050815Z [err]    File "/app/.venv/lib/python3.11/site-packages/keras/src/layers/serialization.py", line 276, in deserialize
2025-10-20T15:54:52.251055822Z [err]      return serialization_lib.deserialize_keras_object(
2025-10-20T15:54:52.251062914Z [err]             ^^^^^^^^^^^^^^^^^^^^^^^^^^^^^^^^^^^^^^^^^^^
2025-10-20T15:54:52.252125810Z [err]    File "/app/.venv/lib/python3.11/site-packages/keras/src/saving/serialization_lib.py", line 609, in deserialize_keras_object
2025-10-20T15:54:52.252133723Z [err]      return deserialize_keras_object(
2025-10-20T15:54:52.252139058Z [err]             ^^^^^^^^^^^^^^^^^^^^^^^^^
2025-10-20T15:54:52.252145940Z [err]    File "/app/.venv/lib/python3.11/site-packages/keras/src/saving/serialization_lib.py", line 728, in deserialize_keras_object
2025-10-20T15:54:52.252151307Z [err]      instance = cls.from_config(inner_config)
2025-10-20T15:54:52.252156169Z [err]                 ^^^^^^^^^^^^^^^^^^^^^^^^^^^^^
2025-10-20T15:54:52.252160896Z [err]    File "/app/.venv/lib/python3.11/site-packages/keras/src/engine/base_layer.py", line 870, in from_config
2025-10-20T15:54:52.252168229Z [err]      raise TypeError(
2025-10-20T15:54:52.252173650Z [err]  TypeError: Error when deserializing class 'InputLayer' using config={'batch_shape': [None, 128, 128, 3], 'dtype': 'float32', 'sparse': False, 'ragged': False, 'name': 'input_layer'}.
2025-10-20T15:54:52.252179124Z [err]
2025-10-20T15:54:52.252184867Z [err]  Exception encountered: Unrecognized keyword arguments: ['batch_shape']
2025-10-20T15:54:52.252190761Z [err]  [2025-10-20 15:54:52 +0000] [2] [INFO] Worker exiting (pid: 2)
2025-10-20T15:54:52.786709746Z [err]  [2025-10-20 15:54:52 +0000] [1] [ERROR] Worker (pid:2) exited with code 3
2025-10-20T15:54:52.786720018Z [err]  [2025-10-20 15:54:52 +0000] [1] [ERROR] Shutting down: Master
2025-10-20T15:54:52.786725400Z [err]  [2025-10-20 15:54:52 +0000] [1] [ERROR] Reason: Worker failed to boot.
2025-10-20T15:54:53.792666192Z [err]  [2025-10-20 15:54:53 +0000] [1] [INFO] Starting gunicorn 21.2.0
2025-10-20T15:54:53.792673662Z [err]  [2025-10-20 15:54:53 +0000] [1] [INFO] Listening at: http://0.0.0.0:8080 (1)
2025-10-20T15:54:53.792680261Z [err]  [2025-10-20 15:54:53 +0000] [1] [INFO] Using worker: sync
2025-10-20T15:54:53.792686337Z [err]  [2025-10-20 15:54:53 +0000] [2] [INFO] Booting worker with pid: 2
2025-10-20T15:54:54.435452436Z [err]  2025-10-20 15:54:54.421893: I tensorflow/core/util/port.cc:113] oneDNN custom operations are on. You may see slightly different numerical results due to floating-point round-off errors from different computation orders. To turn them off, set the environment variable `TF_ENABLE_ONEDNN_OPTS=0`.
2025-10-20T15:54:54.435462380Z [err]  2025-10-20 15:54:54.424878: I external/local_tsl/tsl/cuda/cudart_stub.cc:31] Could not find cuda drivers on your machine, GPU will not be used.
2025-10-20T15:54:54.472414694Z [err]  2025-10-20 15:54:54.467877: E external/local_xla/xla/stream_executor/cuda/cuda_dnn.cc:9261] Unable to register cuDNN factory: Attempting to register factory for plugin cuDNN when one has already been registered
2025-10-20T15:54:54.472422324Z [err]  2025-10-20 15:54:54.467929: E external/local_xla/xla/stream_executor/cuda/cuda_fft.cc:607] Unable to register cuFFT factory: Attempting to register factory for plugin cuFFT when one has already been registered
2025-10-20T15:54:54.472428583Z [err]  2025-10-20 15:54:54.469727: E external/local_xla/xla/stream_executor/cuda/cuda_blas.cc:1515] Unable to register cuBLAS factory: Attempting to register factory for plugin cuBLAS when one has already been registered
2025-10-20T15:54:54.484281906Z [err]  2025-10-20 15:54:54.477998: I external/local_tsl/tsl/cuda/cudart_stub.cc:31] Could not find cuda drivers on your machine, GPU will not be used.
2025-10-20T15:54:54.484291371Z [err]  2025-10-20 15:54:54.478272: I tensorflow/core/platform/cpu_feature_guard.cc:182] This TensorFlow binary is optimized to use available CPU instructions in performance-critical operations.
2025-10-20T15:54:54.484298427Z [err]  To enable the following instructions: AVX2 AVX512F AVX512_VNNI AVX512_BF16 AVX_VNNI AMX_TILE AMX_INT8 AMX_BF16 FMA, in other operations, rebuild TensorFlow with the appropriate compiler flags.
2025-10-20T15:54:55.410195911Z [err]  2025-10-20 15:54:55.391217: W tensorflow/compiler/tf2tensorrt/utils/py_utils.cc:38] TF-TRT Warning: Could not find TensorRT
2025-10-20T15:54:56.264429287Z [err]    File "/app/.venv/lib/python3.11/site-packages/gunicorn/app/base.py", line 67, in wsgi
2025-10-20T15:54:56.264489796Z [err]  [2025-10-20 15:54:56 +0000] [2] [ERROR] Exception in worker process
2025-10-20T15:54:56.264496786Z [err]  Traceback (most recent call last):
2025-10-20T15:54:56.264505478Z [err]    File "/app/.venv/lib/python3.11/site-packages/keras/src/engine/base_layer.py", line 868, in from_config
2025-10-20T15:54:56.264513994Z [err]      return cls(**config)
2025-10-20T15:54:56.264520168Z [err]             ^^^^^^^^^^^^^
2025-10-20T15:54:56.264526184Z [err]    File "/app/.venv/lib/python3.11/site-packages/keras/src/utils/traceback_utils.py", line 70, in error_handler
2025-10-20T15:54:56.264542313Z [err]      raise e.with_traceback(filtered_tb) from None
2025-10-20T15:54:56.264549641Z [err]    File "/app/.venv/lib/python3.11/site-packages/keras/src/engine/input_layer.py", line 153, in __init__
2025-10-20T15:54:56.264556467Z [err]      raise ValueError(
2025-10-20T15:54:56.264565471Z [err]  ValueError: Unrecognized keyword arguments: ['batch_shape']
2025-10-20T15:54:56.264580251Z [err]
2025-10-20T15:54:56.264594474Z [err]      return _bootstrap._gcd_import(name[level:], package, level)
2025-10-20T15:54:56.264603206Z [err]  During handling of the above exception, another exception occurred:
2025-10-20T15:54:56.264608156Z [err]             ^^^^^^^^^^^^^^^^^^^^^^^^^^^^^^^^^^^^^^^^^^^^^^^^^^^^
2025-10-20T15:54:56.264616923Z [err]
2025-10-20T15:54:56.264625785Z [err]    File "<frozen importlib._bootstrap>", line 1206, in _gcd_import
2025-10-20T15:54:56.264630707Z [err]  Traceback (most recent call last):
2025-10-20T15:54:56.264635395Z [err]      self.callable = self.load()
2025-10-20T15:54:56.264646750Z [err]    File "<frozen importlib._bootstrap>", line 1178, in _find_and_load
2025-10-20T15:54:56.264646827Z [err]                      ^^^^^^^^^^^
2025-10-20T15:54:56.264648766Z [err]    File "/app/.venv/lib/python3.11/site-packages/gunicorn/arbiter.py", line 609, in spawn_worker
2025-10-20T15:54:56.264658650Z [err]    File "<frozen importlib._bootstrap>", line 1149, in _find_and_load_unlocked
2025-10-20T15:54:56.264658677Z [err]    File "/app/.venv/lib/python3.11/site-packages/gunicorn/app/wsgiapp.py", line 58, in load
2025-10-20T15:54:56.264666319Z [err]      worker.init_process()
2025-10-20T15:54:56.264671333Z [err]      return self.load_wsgiapp()
2025-10-20T15:54:56.264673036Z [err]    File "<frozen importlib._bootstrap>", line 690, in _load_unlocked
2025-10-20T15:54:56.264682642Z [err]    File "/app/.venv/lib/python3.11/site-packages/gunicorn/workers/base.py", line 134, in init_process
2025-10-20T15:54:56.264684668Z [err]             ^^^^^^^^^^^^^^^^^^^
2025-10-20T15:54:56.264687252Z [err]    File "<frozen importlib._bootstrap_external>", line 940, in exec_module
2025-10-20T15:54:56.264696968Z [err]    File "/app/.venv/lib/python3.11/site-packages/gunicorn/app/wsgiapp.py", line 48, in load_wsgiapp
2025-10-20T15:54:56.264698366Z [err]    File "<frozen importlib._bootstrap>", line 241, in _call_with_frames_removed
2025-10-20T15:54:56.264699520Z [err]      self.load_wsgi()
2025-10-20T15:54:56.264709675Z [err]      return util.import_app(self.app_uri)
2025-10-20T15:54:56.264714529Z [err]    File "/app/.venv/lib/python3.11/site-packages/gunicorn/workers/base.py", line 146, in load_wsgi
2025-10-20T15:54:56.264719764Z [err]             ^^^^^^^^^^^^^^^^^^^^^^^^^^^^^
2025-10-20T15:54:56.264729235Z [err]      self.wsgi = self.app.wsgi()
2025-10-20T15:54:56.264732883Z [err]    File "/app/.venv/lib/python3.11/site-packages/gunicorn/util.py", line 371, in import_app
2025-10-20T15:54:56.264740085Z [err]                  ^^^^^^^^^^^^^^^
2025-10-20T15:54:56.264744177Z [err]      mod = importlib.import_module(module)
2025-10-20T15:54:56.264751470Z [err]            ^^^^^^^^^^^^^^^^^^^^^^^^^^^^^^^
2025-10-20T15:54:56.264756306Z [err]    File "/mise/installs/python/3.11.0/lib/python3.11/importlib/__init__.py", line 126, in import_module
2025-10-20T15:54:56.265822025Z [err]    File "/app/api.py", line 19, in <module>
2025-10-20T15:54:56.265829276Z [err]      model = keras.models.load_model(model_path)
2025-10-20T15:54:56.265835333Z [err]              ^^^^^^^^^^^^^^^^^^^^^^^^^^^^^^^^^^^
2025-10-20T15:54:56.265841090Z [err]    File "/app/.venv/lib/python3.11/site-packages/keras/src/saving/saving_api.py", line 254, in load_model
2025-10-20T15:54:56.265847556Z [err]      return saving_lib.load_model(
2025-10-20T15:54:56.265855140Z [err]             ^^^^^^^^^^^^^^^^^^^^^^
2025-10-20T15:54:56.265878994Z [err]    File "/app/.venv/lib/python3.11/site-packages/keras/src/saving/saving_lib.py", line 281, in load_model
2025-10-20T15:54:56.265885010Z [err]      raise e
2025-10-20T15:54:56.265889859Z [err]    File "/app/.venv/lib/python3.11/site-packages/keras/src/saving/saving_lib.py", line 246, in load_model
2025-10-20T15:54:56.265894957Z [err]      model = deserialize_keras_object(
2025-10-20T15:54:56.265900653Z [err]              ^^^^^^^^^^^^^^^^^^^^^^^^^
2025-10-20T15:54:56.265905757Z [err]    File "/app/.venv/lib/python3.11/site-packages/keras/src/saving/serialization_lib.py", line 728, in deserialize_keras_object
2025-10-20T15:54:56.265910238Z [err]      instance = cls.from_config(inner_config)
2025-10-20T15:54:56.265915111Z [err]                 ^^^^^^^^^^^^^^^^^^^^^^^^^^^^^
2025-10-20T15:54:56.265927248Z [err]    File "/app/.venv/lib/python3.11/site-packages/keras/src/engine/sequential.py", line 466, in from_config
2025-10-20T15:54:56.265932850Z [err]      layer = layer_module.deserialize(
2025-10-20T15:54:56.265941886Z [err]              ^^^^^^^^^^^^^^^^^^^^^^^^^
2025-10-20T15:54:56.265949061Z [err]    File "/app/.venv/lib/python3.11/site-packages/keras/src/layers/serialization.py", line 276, in deserialize
2025-10-20T15:54:56.265955413Z [err]      return serialization_lib.deserialize_keras_object(
2025-10-20T15:54:56.265960930Z [err]             ^^^^^^^^^^^^^^^^^^^^^^^^^^^^^^^^^^^^^^^^^^^
2025-10-20T15:54:56.266585465Z [err]    File "/app/.venv/lib/python3.11/site-packages/keras/src/saving/serialization_lib.py", line 609, in deserialize_keras_object
2025-10-20T15:54:56.266595256Z [err]      return deserialize_keras_object(
2025-10-20T15:54:56.266602183Z [err]             ^^^^^^^^^^^^^^^^^^^^^^^^^
2025-10-20T15:54:56.266608174Z [err]    File "/app/.venv/lib/python3.11/site-packages/keras/src/saving/serialization_lib.py", line 728, in deserialize_keras_object
2025-10-20T15:54:56.266613865Z [err]      instance = cls.from_config(inner_config)
2025-10-20T15:54:56.266621469Z [err]                 ^^^^^^^^^^^^^^^^^^^^^^^^^^^^^
2025-10-20T15:54:56.266628325Z [err]    File "/app/.venv/lib/python3.11/site-packages/keras/src/engine/base_layer.py", line 870, in from_config
2025-10-20T15:54:56.266634910Z [err]      raise TypeError(
2025-10-20T15:54:56.266640808Z [err]  TypeError: Error when deserializing class 'InputLayer' using config={'batch_shape': [None, 128, 128, 3], 'dtype': 'float32', 'sparse': False, 'ragged': False, 'name': 'input_layer'}.
2025-10-20T15:54:56.266645324Z [err]
2025-10-20T15:54:56.266651038Z [err]  Exception encountered: Unrecognized keyword arguments: ['batch_shape']
2025-10-20T15:54:56.266656221Z [err]  [2025-10-20 15:54:56 +0000] [2] [INFO] Worker exiting (pid: 2)
2025-10-20T15:54:56.917789503Z [err]  [2025-10-20 15:54:56 +0000] [1] [ERROR] Worker (pid:2) exited with code 3
2025-10-20T15:54:56.917795057Z [err]  [2025-10-20 15:54:56 +0000] [1] [ERROR] Shutting down: Master
2025-10-20T15:54:56.917799966Z [err]  [2025-10-20 15:54:56 +0000] [1] [ERROR] Reason: Worker failed to boot.
2025-10-20T15:54:58.778176120Z [err]  [2025-10-20 15:54:58 +0000] [1] [INFO] Starting gunicorn 21.2.0
2025-10-20T15:54:58.778183394Z [err]  [2025-10-20 15:54:58 +0000] [1] [INFO] Listening at: http://0.0.0.0:8080 (1)
2025-10-20T15:54:58.778190256Z [err]  [2025-10-20 15:54:58 +0000] [1] [INFO] Using worker: sync
2025-10-20T15:54:58.785084668Z [err]  [2025-10-20 15:54:58 +0000] [2] [INFO] Booting worker with pid: 2
2025-10-20T15:54:59.440294845Z [err]  2025-10-20 15:54:59.435198: I tensorflow/core/util/port.cc:113] oneDNN custom operations are on. You may see slightly different numerical results due to floating-point round-off errors from different computation orders. To turn them off, set the environment variable `TF_ENABLE_ONEDNN_OPTS=0`.
2025-10-20T15:54:59.440304776Z [err]  2025-10-20 15:54:59.437985: I external/local_tsl/tsl/cuda/cudart_stub.cc:31] Could not find cuda drivers on your machine, GPU will not be used.
2025-10-20T15:54:59.481237841Z [err]  2025-10-20 15:54:59.479227: E external/local_xla/xla/stream_executor/cuda/cuda_dnn.cc:9261] Unable to register cuDNN factory: Attempting to register factory for plugin cuDNN when one has already been registered
2025-10-20T15:54:59.481242636Z [err]  2025-10-20 15:54:59.479280: E external/local_xla/xla/stream_executor/cuda/cuda_fft.cc:607] Unable to register cuFFT factory: Attempting to register factory for plugin cuFFT when one has already been registered
2025-10-20T15:54:59.482943030Z [err]  2025-10-20 15:54:59.481130: E external/local_xla/xla/stream_executor/cuda/cuda_blas.cc:1515] Unable to register cuBLAS factory: Attempting to register factory for plugin cuBLAS when one has already been registered
2025-10-20T15:54:59.492075558Z [err]  2025-10-20 15:54:59.490316: I external/local_tsl/tsl/cuda/cudart_stub.cc:31] Could not find cuda drivers on your machine, GPU will not be used.
2025-10-20T15:54:59.492085939Z [err]  2025-10-20 15:54:59.490622: I tensorflow/core/platform/cpu_feature_guard.cc:182] This TensorFlow binary is optimized to use available CPU instructions in performance-critical operations.
2025-10-20T15:54:59.492092325Z [err]  To enable the following instructions: AVX2 AVX512F AVX512_VNNI AVX512_BF16 AVX_VNNI AMX_TILE AMX_INT8 AMX_BF16 FMA, in other operations, rebuild TensorFlow with the appropriate compiler flags.
2025-10-20T15:55:00.463169277Z [err]  2025-10-20 15:55:00.461268: W tensorflow/compiler/tf2tensorrt/utils/py_utils.cc:38] TF-TRT Warning: Could not find TensorRT
2025-10-20T15:55:01.450710537Z [err]  [2025-10-20 15:55:01 +0000] [2] [ERROR] Exception in worker process
2025-10-20T15:55:01.450717276Z [err]  Traceback (most recent call last):
2025-10-20T15:55:01.450723046Z [err]    File "/app/.venv/lib/python3.11/site-packages/keras/src/engine/base_layer.py", line 868, in from_config
2025-10-20T15:55:01.450728196Z [err]      return cls(**config)
2025-10-20T15:55:01.450733987Z [err]             ^^^^^^^^^^^^^
2025-10-20T15:55:01.450742804Z [err]    File "/app/.venv/lib/python3.11/site-packages/keras/src/utils/traceback_utils.py", line 70, in error_handler
2025-10-20T15:55:01.450771984Z [err]      raise e.with_traceback(filtered_tb) from None
2025-10-20T15:55:01.450778374Z [err]    File "/app/.venv/lib/python3.11/site-packages/keras/src/engine/input_layer.py", line 153, in __init__
2025-10-20T15:55:01.450783786Z [err]      raise ValueError(
2025-10-20T15:55:01.450789261Z [err]  ValueError: Unrecognized keyword arguments: ['batch_shape']
2025-10-20T15:55:01.450794536Z [err]
2025-10-20T15:55:01.450798319Z [err]    File "/app/.venv/lib/python3.11/site-packages/gunicorn/arbiter.py", line 609, in spawn_worker
2025-10-20T15:55:01.450800022Z [err]  During handling of the above exception, another exception occurred:
2025-10-20T15:55:01.450806706Z [err]
2025-10-20T15:55:01.450810357Z [err]      worker.init_process()
2025-10-20T15:55:01.450812807Z [err]  Traceback (most recent call last):
2025-10-20T15:55:01.450819875Z [err]    File "/app/.venv/lib/python3.11/site-packages/gunicorn/workers/base.py", line 134, in init_process
2025-10-20T15:55:01.450828179Z [err]      self.load_wsgi()
2025-10-20T15:55:01.450835952Z [err]    File "/app/.venv/lib/python3.11/site-packages/gunicorn/workers/base.py", line 146, in load_wsgi
2025-10-20T15:55:01.450842810Z [err]      self.wsgi = self.app.wsgi()
2025-10-20T15:55:01.450851603Z [err]                  ^^^^^^^^^^^^^^^
2025-10-20T15:55:01.450857948Z [err]    File "/app/.venv/lib/python3.11/site-packages/gunicorn/app/base.py", line 67, in wsgi
2025-10-20T15:55:01.451334417Z [err]      self.callable = self.load()
2025-10-20T15:55:01.451342371Z [err]                      ^^^^^^^^^^^
2025-10-20T15:55:01.451347605Z [err]    File "/app/.venv/lib/python3.11/site-packages/gunicorn/app/wsgiapp.py", line 58, in load
2025-10-20T15:55:01.451353256Z [err]      return self.load_wsgiapp()
2025-10-20T15:55:01.451357950Z [err]             ^^^^^^^^^^^^^^^^^^^
2025-10-20T15:55:01.451362187Z [err]    File "/app/.venv/lib/python3.11/site-packages/gunicorn/app/wsgiapp.py", line 48, in load_wsgiapp
2025-10-20T15:55:01.451367609Z [err]      return util.import_app(self.app_uri)
2025-10-20T15:55:01.451371987Z [err]             ^^^^^^^^^^^^^^^^^^^^^^^^^^^^^
2025-10-20T15:55:01.451376936Z [err]    File "/app/.venv/lib/python3.11/site-packages/gunicorn/util.py", line 371, in import_app
2025-10-20T15:55:01.451381272Z [err]      mod = importlib.import_module(module)
2025-10-20T15:55:01.451386322Z [err]            ^^^^^^^^^^^^^^^^^^^^^^^^^^^^^^^
2025-10-20T15:55:01.451391235Z [err]    File "/mise/installs/python/3.11.0/lib/python3.11/importlib/__init__.py", line 126, in import_module
2025-10-20T15:55:01.451395810Z [err]      return _bootstrap._gcd_import(name[level:], package, level)
2025-10-20T15:55:01.451400108Z [err]             ^^^^^^^^^^^^^^^^^^^^^^^^^^^^^^^^^^^^^^^^^^^^^^^^^^^^
2025-10-20T15:55:01.451404126Z [err]    File "<frozen importlib._bootstrap>", line 1206, in _gcd_import
2025-10-20T15:55:01.451408072Z [err]    File "<frozen importlib._bootstrap>", line 1178, in _find_and_load
2025-10-20T15:55:01.451412697Z [err]    File "<frozen importlib._bootstrap>", line 1149, in _find_and_load_unlocked
2025-10-20T15:55:01.451417148Z [err]    File "<frozen importlib._bootstrap>", line 690, in _load_unlocked
2025-10-20T15:55:01.451422580Z [err]    File "<frozen importlib._bootstrap_external>", line 940, in exec_module
2025-10-20T15:55:01.451427707Z [err]    File "<frozen importlib._bootstrap>", line 241, in _call_with_frames_removed
2025-10-20T15:55:01.452092646Z [err]    File "/app/api.py", line 19, in <module>
2025-10-20T15:55:01.452098964Z [err]      model = keras.models.load_model(model_path)
2025-10-20T15:55:01.452106213Z [err]    File "/app/.venv/lib/python3.11/site-packages/keras/src/saving/saving_lib.py", line 281, in load_model
2025-10-20T15:55:01.452106760Z [err]      layer = layer_module.deserialize(
2025-10-20T15:55:01.452107755Z [err]              ^^^^^^^^^^^^^^^^^^^^^^^^^^^^^^^^^^^
2025-10-20T15:55:01.452112862Z [err]      raise e
2025-10-20T15:55:01.452115271Z [err]    File "/app/.venv/lib/python3.11/site-packages/keras/src/saving/saving_api.py", line 254, in load_model
2025-10-20T15:55:01.452118920Z [err]    File "/app/.venv/lib/python3.11/site-packages/keras/src/saving/saving_lib.py", line 246, in load_model
2025-10-20T15:55:01.452124278Z [err]      return saving_lib.load_model(
2025-10-20T15:55:01.452124491Z [err]              ^^^^^^^^^^^^^^^^^^^^^^^^^
2025-10-20T15:55:01.452125995Z [err]      model = deserialize_keras_object(
2025-10-20T15:55:01.452132695Z [err]    File "/app/.venv/lib/python3.11/site-packages/keras/src/layers/serialization.py", line 276, in deserialize
2025-10-20T15:55:01.452134174Z [err]              ^^^^^^^^^^^^^^^^^^^^^^^^^
2025-10-20T15:55:01.452134499Z [err]             ^^^^^^^^^^^^^^^^^^^^^^
2025-10-20T15:55:01.452140519Z [err]    File "/app/.venv/lib/python3.11/site-packages/keras/src/saving/serialization_lib.py", line 728, in deserialize_keras_object
2025-10-20T15:55:01.452141599Z [err]      return serialization_lib.deserialize_keras_object(
2025-10-20T15:55:01.452146217Z [err]      instance = cls.from_config(inner_config)
2025-10-20T15:55:01.452149050Z [err]             ^^^^^^^^^^^^^^^^^^^^^^^^^^^^^^^^^^^^^^^^^^^
2025-10-20T15:55:01.452151433Z [err]                 ^^^^^^^^^^^^^^^^^^^^^^^^^^^^^
2025-10-20T15:55:01.452155278Z [err]    File "/app/.venv/lib/python3.11/site-packages/keras/src/engine/sequential.py", line 466, in from_config
2025-10-20T15:55:01.452723152Z [err]    File "/app/.venv/lib/python3.11/site-packages/keras/src/saving/serialization_lib.py", line 609, in deserialize_keras_object
2025-10-20T15:55:01.452728846Z [err]      return deserialize_keras_object(
2025-10-20T15:55:01.452735121Z [err]             ^^^^^^^^^^^^^^^^^^^^^^^^^
2025-10-20T15:55:01.452739216Z [err]    File "/app/.venv/lib/python3.11/site-packages/keras/src/saving/serialization_lib.py", line 728, in deserialize_keras_object
2025-10-20T15:55:01.452743077Z [err]      instance = cls.from_config(inner_config)
2025-10-20T15:55:01.452747181Z [err]                 ^^^^^^^^^^^^^^^^^^^^^^^^^^^^^
2025-10-20T15:55:01.452751369Z [err]    File "/app/.venv/lib/python3.11/site-packages/keras/src/engine/base_layer.py", line 870, in from_config
2025-10-20T15:55:01.452755711Z [err]      raise TypeError(
2025-10-20T15:55:01.452759680Z [err]  TypeError: Error when deserializing class 'InputLayer' using config={'batch_shape': [None, 128, 128, 3], 'dtype': 'float32', 'sparse': False, 'ragged': False, 'name': 'input_layer'}.
2025-10-20T15:55:01.452763995Z [err]
2025-10-20T15:55:01.452768157Z [err]  Exception encountered: Unrecognized keyword arguments: ['batch_shape']
2025-10-20T15:55:01.452772201Z [err]  [2025-10-20 15:55:01 +0000] [2] [INFO] Worker exiting (pid: 2)
2025-10-20T15:55:02.352300923Z [err]  [2025-10-20 15:55:02 +0000] [1] [ERROR] Worker (pid:2) exited with code 3
2025-10-20T15:55:02.352308921Z [err]  [2025-10-20 15:55:02 +0000] [1] [ERROR] Shutting down: Master
2025-10-20T15:55:02.352314110Z [err]  [2025-10-20 15:55:02 +0000] [1] [ERROR] Reason: Worker failed to boot.
2025-10-20T15:55:03.488299151Z [err]  [2025-10-20 15:55:03 +0000] [1] [INFO] Starting gunicorn 21.2.0
2025-10-20T15:55:03.488305989Z [err]  [2025-10-20 15:55:03 +0000] [1] [INFO] Listening at: http://0.0.0.0:8080 (1)
2025-10-20T15:55:03.488313235Z [err]  [2025-10-20 15:55:03 +0000] [1] [INFO] Using worker: sync
2025-10-20T15:55:03.488320939Z [err]  [2025-10-20 15:55:03 +0000] [2] [INFO] Booting worker with pid: 2
2025-10-20T15:55:04.337601063Z [err]  2025-10-20 15:55:04.192403: E external/local_xla/xla/stream_executor/cuda/cuda_blas.cc:1515] Unable to register cuBLAS factory: Attempting to register factory for plugin cuBLAS when one has already been registered
2025-10-20T15:55:04.337612476Z [err]  2025-10-20 15:55:04.200222: I external/local_tsl/tsl/cuda/cudart_stub.cc:31] Could not find cuda drivers on your machine, GPU will not be used.
2025-10-20T15:55:04.337620619Z [err]  2025-10-20 15:55:04.200501: I tensorflow/core/platform/cpu_feature_guard.cc:182] This TensorFlow binary is optimized to use available CPU instructions in performance-critical operations.
2025-10-20T15:55:04.337627159Z [err]  To enable the following instructions: AVX2 AVX512F AVX512_VNNI AVX512_BF16 AVX_VNNI AMX_TILE AMX_INT8 AMX_BF16 FMA, in other operations, rebuild TensorFlow with the appropriate compiler flags.
2025-10-20T15:55:04.337711558Z [err]  2025-10-20 15:55:04.143566: I tensorflow/core/util/port.cc:113] oneDNN custom operations are on. You may see slightly different numerical results due to floating-point round-off errors from different computation orders. To turn them off, set the environment variable `TF_ENABLE_ONEDNN_OPTS=0`.
2025-10-20T15:55:04.337715691Z [err]  2025-10-20 15:55:04.146441: I external/local_tsl/tsl/cuda/cudart_stub.cc:31] Could not find cuda drivers on your machine, GPU will not be used.
2025-10-20T15:55:04.337719800Z [err]  2025-10-20 15:55:04.190444: E external/local_xla/xla/stream_executor/cuda/cuda_dnn.cc:9261] Unable to register cuDNN factory: Attempting to register factory for plugin cuDNN when one has already been registered
2025-10-20T15:55:04.337724379Z [err]  2025-10-20 15:55:04.190488: E external/local_xla/xla/stream_executor/cuda/cuda_fft.cc:607] Unable to register cuFFT factory: Attempting to register factory for plugin cuFFT when one has already been registered
2025-10-20T15:55:05.301433123Z [err]  2025-10-20 15:55:05.189803: W tensorflow/compiler/tf2tensorrt/utils/py_utils.cc:38] TF-TRT Warning: Could not find TensorRT
2025-10-20T15:55:06.316609269Z [err]  [2025-10-20 15:55:06 +0000] [2] [ERROR] Exception in worker process
2025-10-20T15:55:06.316614450Z [err]  Traceback (most recent call last):
2025-10-20T15:55:06.316619622Z [err]    File "/app/.venv/lib/python3.11/site-packages/keras/src/engine/base_layer.py", line 868, in from_config
2025-10-20T15:55:06.316626365Z [err]      return cls(**config)
2025-10-20T15:55:06.316631871Z [err]             ^^^^^^^^^^^^^
2025-10-20T15:55:06.316637316Z [err]    File "/app/.venv/lib/python3.11/site-packages/keras/src/utils/traceback_utils.py", line 70, in error_handler
2025-10-20T15:55:06.316642665Z [err]      raise e.with_traceback(filtered_tb) from None
2025-10-20T15:55:06.316648955Z [err]    File "/app/.venv/lib/python3.11/site-packages/keras/src/engine/input_layer.py", line 153, in __init__
2025-10-20T15:55:06.316654359Z [err]      raise ValueError(
2025-10-20T15:55:06.316662265Z [err]  ValueError: Unrecognized keyword arguments: ['batch_shape']
2025-10-20T15:55:06.316667791Z [err]
2025-10-20T15:55:06.316673192Z [err]  During handling of the above exception, another exception occurred:
2025-10-20T15:55:06.316678711Z [err]
2025-10-20T15:55:06.316684550Z [err]  Traceback (most recent call last):
2025-10-20T15:55:06.316689880Z [err]    File "/app/.venv/lib/python3.11/site-packages/gunicorn/arbiter.py", line 609, in spawn_worker
2025-10-20T15:55:06.316695404Z [err]      worker.init_process()
2025-10-20T15:55:06.316700804Z [err]    File "/app/.venv/lib/python3.11/site-packages/gunicorn/workers/base.py", line 134, in init_process
2025-10-20T15:55:06.316705868Z [err]      self.load_wsgi()
2025-10-20T15:55:06.316711195Z [err]    File "/app/.venv/lib/python3.11/site-packages/gunicorn/workers/base.py", line 146, in load_wsgi
2025-10-20T15:55:06.316716687Z [err]      self.wsgi = self.app.wsgi()
2025-10-20T15:55:06.316722090Z [err]                  ^^^^^^^^^^^^^^^
2025-10-20T15:55:06.316728146Z [err]    File "/app/.venv/lib/python3.11/site-packages/gunicorn/app/base.py", line 67, in wsgi
2025-10-20T15:55:06.317117927Z [err]      self.callable = self.load()
2025-10-20T15:55:06.317124802Z [err]                      ^^^^^^^^^^^
2025-10-20T15:55:06.317131262Z [err]    File "/app/.venv/lib/python3.11/site-packages/gunicorn/app/wsgiapp.py", line 58, in load
2025-10-20T15:55:06.317137860Z [err]      return self.load_wsgiapp()
2025-10-20T15:55:06.317143973Z [err]             ^^^^^^^^^^^^^^^^^^^
2025-10-20T15:55:06.317149746Z [err]    File "/app/.venv/lib/python3.11/site-packages/gunicorn/app/wsgiapp.py", line 48, in load_wsgiapp
2025-10-20T15:55:06.317155456Z [err]      return util.import_app(self.app_uri)
2025-10-20T15:55:06.317161047Z [err]             ^^^^^^^^^^^^^^^^^^^^^^^^^^^^^
2025-10-20T15:55:06.317166768Z [err]    File "/app/.venv/lib/python3.11/site-packages/gunicorn/util.py", line 371, in import_app
2025-10-20T15:55:06.317171980Z [err]      mod = importlib.import_module(module)
2025-10-20T15:55:06.317177789Z [err]            ^^^^^^^^^^^^^^^^^^^^^^^^^^^^^^^
2025-10-20T15:55:06.317183655Z [err]    File "/mise/installs/python/3.11.0/lib/python3.11/importlib/__init__.py", line 126, in import_module
2025-10-20T15:55:06.317188971Z [err]      return _bootstrap._gcd_import(name[level:], package, level)
2025-10-20T15:55:06.317194214Z [err]             ^^^^^^^^^^^^^^^^^^^^^^^^^^^^^^^^^^^^^^^^^^^^^^^^^^^^
2025-10-20T15:55:06.317200634Z [err]    File "<frozen importlib._bootstrap>", line 1206, in _gcd_import
2025-10-20T15:55:06.317206347Z [err]    File "<frozen importlib._bootstrap>", line 1178, in _find_and_load
2025-10-20T15:55:06.317212987Z [err]    File "<frozen importlib._bootstrap>", line 1149, in _find_and_load_unlocked
2025-10-20T15:55:06.317218489Z [err]    File "<frozen importlib._bootstrap>", line 690, in _load_unlocked
2025-10-20T15:55:06.317223814Z [err]    File "<frozen importlib._bootstrap_external>", line 940, in exec_module
2025-10-20T15:55:06.317229139Z [err]    File "<frozen importlib._bootstrap>", line 241, in _call_with_frames_removed
2025-10-20T15:55:06.318716708Z [err]    File "/app/.venv/lib/python3.11/site-packages/keras/src/saving/serialization_lib.py", line 728, in deserialize_keras_object
2025-10-20T15:55:06.318728714Z [err]      instance = cls.from_config(inner_config)
2025-10-20T15:55:06.318736557Z [err]                 ^^^^^^^^^^^^^^^^^^^^^^^^^^^^^
2025-10-20T15:55:06.318742295Z [err]    File "/app/.venv/lib/python3.11/site-packages/keras/src/engine/sequential.py", line 466, in from_config
2025-10-20T15:55:06.318747573Z [err]      layer = layer_module.deserialize(
2025-10-20T15:55:06.318754238Z [err]              ^^^^^^^^^^^^^^^^^^^^^^^^^
2025-10-20T15:55:06.318758949Z [err]    File "/app/.venv/lib/python3.11/site-packages/keras/src/layers/serialization.py", line 276, in deserialize
2025-10-20T15:55:06.318765129Z [err]      return serialization_lib.deserialize_keras_object(
2025-10-20T15:55:06.318767354Z [err]    File "/app/api.py", line 19, in <module>
2025-10-20T15:55:06.318771577Z [err]             ^^^^^^^^^^^^^^^^^^^^^^^^^^^^^^^^^^^^^^^^^^^
2025-10-20T15:55:06.318776676Z [err]      model = keras.models.load_model(model_path)
2025-10-20T15:55:06.318783211Z [err]              ^^^^^^^^^^^^^^^^^^^^^^^^^^^^^^^^^^^
2025-10-20T15:55:06.318788857Z [err]    File "/app/.venv/lib/python3.11/site-packages/keras/src/saving/saving_api.py", line 254, in load_model
2025-10-20T15:55:06.318794354Z [err]      return saving_lib.load_model(
2025-10-20T15:55:06.318800655Z [err]             ^^^^^^^^^^^^^^^^^^^^^^
2025-10-20T15:55:06.318806988Z [err]    File "/app/.venv/lib/python3.11/site-packages/keras/src/saving/saving_lib.py", line 281, in load_model
2025-10-20T15:55:06.318812808Z [err]      raise e
2025-10-20T15:55:06.318818701Z [err]    File "/app/.venv/lib/python3.11/site-packages/keras/src/saving/saving_lib.py", line 246, in load_model
2025-10-20T15:55:06.318825082Z [err]      model = deserialize_keras_object(
2025-10-20T15:55:06.318830901Z [err]              ^^^^^^^^^^^^^^^^^^^^^^^^^
2025-10-20T15:55:06.319307448Z [err]    File "/app/.venv/lib/python3.11/site-packages/keras/src/saving/serialization_lib.py", line 609, in deserialize_keras_object
2025-10-20T15:55:06.319315980Z [err]      return deserialize_keras_object(
2025-10-20T15:55:06.319323015Z [err]             ^^^^^^^^^^^^^^^^^^^^^^^^^
2025-10-20T15:55:06.319327937Z [err]    File "/app/.venv/lib/python3.11/site-packages/keras/src/saving/serialization_lib.py", line 728, in deserialize_keras_object
2025-10-20T15:55:06.319334951Z [err]      instance = cls.from_config(inner_config)
2025-10-20T15:55:06.319340511Z [err]                 ^^^^^^^^^^^^^^^^^^^^^^^^^^^^^
2025-10-20T15:55:06.319345282Z [err]    File "/app/.venv/lib/python3.11/site-packages/keras/src/engine/base_layer.py", line 870, in from_config
2025-10-20T15:55:06.319350270Z [err]      raise TypeError(
2025-10-20T15:55:06.319355027Z [err]  TypeError: Error when deserializing class 'InputLayer' using config={'batch_shape': [None, 128, 128, 3], 'dtype': 'float32', 'sparse': False, 'ragged': False, 'name': 'input_layer'}.
2025-10-20T15:55:06.319361628Z [err]
2025-10-20T15:55:06.319366078Z [err]  Exception encountered: Unrecognized keyword arguments: ['batch_shape']
2025-10-20T15:55:06.319370148Z [err]  [2025-10-20 15:55:06 +0000] [2] [INFO] Worker exiting (pid: 2)
2025-10-20T15:55:06.988638234Z [err]  [2025-10-20 15:55:06 +0000] [1] [ERROR] Worker (pid:2) exited with code 3
2025-10-20T15:55:06.988649110Z [err]  [2025-10-20 15:55:06 +0000] [1] [ERROR] Shutting down: Master
2025-10-20T15:55:06.988656727Z [err]  [2025-10-20 15:55:06 +0000] [1] [ERROR] Reason: Worker failed to boot.
2025-10-20T15:55:08.555436311Z [err]  [2025-10-20 15:55:08 +0000] [1] [INFO] Starting gunicorn 21.2.0
2025-10-20T15:55:08.555446056Z [err]  [2025-10-20 15:55:08 +0000] [1] [INFO] Listening at: http://0.0.0.0:8080 (1)
2025-10-20T15:55:08.555453740Z [err]  [2025-10-20 15:55:08 +0000] [1] [INFO] Using worker: sync
2025-10-20T15:55:08.555459739Z [err]  [2025-10-20 15:55:08 +0000] [2] [INFO] Booting worker with pid: 2
2025-10-20T15:55:09.383752995Z [err]  2025-10-20 15:55:09.298340: I tensorflow/core/util/port.cc:113] oneDNN custom operations are on. You may see slightly different numerical results due to floating-point round-off errors from different computation orders. To turn them off, set the environment variable `TF_ENABLE_ONEDNN_OPTS=0`.
2025-10-20T15:55:09.383758614Z [err]  2025-10-20 15:55:09.300934: I external/local_tsl/tsl/cuda/cudart_stub.cc:31] Could not find cuda drivers on your machine, GPU will not be used.
2025-10-20T15:55:09.383766034Z [err]  2025-10-20 15:55:09.339630: E external/local_xla/xla/stream_executor/cuda/cuda_dnn.cc:9261] Unable to register cuDNN factory: Attempting to register factory for plugin cuDNN when one has already been registered
2025-10-20T15:55:09.383772344Z [err]  2025-10-20 15:55:09.339673: E external/local_xla/xla/stream_executor/cuda/cuda_fft.cc:607] Unable to register cuFFT factory: Attempting to register factory for plugin cuFFT when one has already been registered
2025-10-20T15:55:09.383778859Z [err]  2025-10-20 15:55:09.341510: E external/local_xla/xla/stream_executor/cuda/cuda_blas.cc:1515] Unable to register cuBLAS factory: Attempting to register factory for plugin cuBLAS when one has already been registered
2025-10-20T15:55:09.383785094Z [err]  2025-10-20 15:55:09.348777: I external/local_tsl/tsl/cuda/cudart_stub.cc:31] Could not find cuda drivers on your machine, GPU will not be used.
2025-10-20T15:55:09.383791153Z [err]  2025-10-20 15:55:09.349042: I tensorflow/core/platform/cpu_feature_guard.cc:182] This TensorFlow binary is optimized to use available CPU instructions in performance-critical operations.
2025-10-20T15:55:09.383796828Z [err]  To enable the following instructions: AVX2 AVX512F AVX512_VNNI AVX512_BF16 AVX_VNNI AMX_TILE AMX_INT8 AMX_BF16 FMA, in other operations, rebuild TensorFlow with the appropriate compiler flags.
2025-10-20T15:55:10.436058903Z [err]  2025-10-20 15:55:10.360758: W tensorflow/compiler/tf2tensorrt/utils/py_utils.cc:38] TF-TRT Warning: Could not find TensorRT
2025-10-20T15:55:11.469205356Z [err]      return cls(**config)
2025-10-20T15:55:11.469214454Z [err]             ^^^^^^^^^^^^^
2025-10-20T15:55:11.469220055Z [err]      self.wsgi = self.app.wsgi()
2025-10-20T15:55:11.469220305Z [err]    File "/app/.venv/lib/python3.11/site-packages/keras/src/utils/traceback_utils.py", line 70, in error_handler
2025-10-20T15:55:11.469225029Z [err]      raise e.with_traceback(filtered_tb) from None
2025-10-20T15:55:11.469230238Z [err]    File "/app/.venv/lib/python3.11/site-packages/keras/src/engine/input_layer.py", line 153, in __init__
2025-10-20T15:55:11.469232045Z [err]                  ^^^^^^^^^^^^^^^
2025-10-20T15:55:11.469237335Z [err]      raise ValueError(
2025-10-20T15:55:11.469240604Z [err]    File "/app/.venv/lib/python3.11/site-packages/gunicorn/app/base.py", line 67, in wsgi
2025-10-20T15:55:11.469248896Z [err]  Traceback (most recent call last):
2025-10-20T15:55:11.469254351Z [err]    File "/app/.venv/lib/python3.11/site-packages/gunicorn/arbiter.py", line 609, in spawn_worker
2025-10-20T15:55:11.469258891Z [err]      worker.init_process()
2025-10-20T15:55:11.469263369Z [err]    File "/app/.venv/lib/python3.11/site-packages/gunicorn/workers/base.py", line 134, in init_process
2025-10-20T15:55:11.469267266Z [err]      self.load_wsgi()
2025-10-20T15:55:11.469272408Z [err]    File "/app/.venv/lib/python3.11/site-packages/gunicorn/workers/base.py", line 146, in load_wsgi
2025-10-20T15:55:11.469293108Z [err]  ValueError: Unrecognized keyword arguments: ['batch_shape']
2025-10-20T15:55:11.469310218Z [err]
2025-10-20T15:55:11.469319197Z [err]  During handling of the above exception, another exception occurred:
2025-10-20T15:55:11.469325654Z [err]
2025-10-20T15:55:11.469451735Z [err]  [2025-10-20 15:55:11 +0000] [2] [ERROR] Exception in worker process
2025-10-20T15:55:11.469457310Z [err]  Traceback (most recent call last):
2025-10-20T15:55:11.469461315Z [err]    File "/app/.venv/lib/python3.11/site-packages/keras/src/engine/base_layer.py", line 868, in from_config
2025-10-20T15:55:11.470201207Z [err]      self.callable = self.load()
2025-10-20T15:55:11.470205067Z [err]                      ^^^^^^^^^^^
2025-10-20T15:55:11.470208793Z [err]    File "/app/.venv/lib/python3.11/site-packages/gunicorn/app/wsgiapp.py", line 58, in load
2025-10-20T15:55:11.470213037Z [err]      return self.load_wsgiapp()
2025-10-20T15:55:11.470217074Z [err]             ^^^^^^^^^^^^^^^^^^^
2025-10-20T15:55:11.470221358Z [err]    File "/app/.venv/lib/python3.11/site-packages/gunicorn/app/wsgiapp.py", line 48, in load_wsgiapp
2025-10-20T15:55:11.470225622Z [err]      return util.import_app(self.app_uri)
2025-10-20T15:55:11.470229788Z [err]             ^^^^^^^^^^^^^^^^^^^^^^^^^^^^^
2025-10-20T15:55:11.470234932Z [err]    File "/app/.venv/lib/python3.11/site-packages/gunicorn/util.py", line 371, in import_app
2025-10-20T15:55:11.470240503Z [err]      mod = importlib.import_module(module)
2025-10-20T15:55:11.470244942Z [err]            ^^^^^^^^^^^^^^^^^^^^^^^^^^^^^^^
2025-10-20T15:55:11.470249179Z [err]    File "/mise/installs/python/3.11.0/lib/python3.11/importlib/__init__.py", line 126, in import_module
2025-10-20T15:55:11.470253510Z [err]      return _bootstrap._gcd_import(name[level:], package, level)
2025-10-20T15:55:11.470257845Z [err]             ^^^^^^^^^^^^^^^^^^^^^^^^^^^^^^^^^^^^^^^^^^^^^^^^^^^^
2025-10-20T15:55:11.470262498Z [err]    File "<frozen importlib._bootstrap>", line 1206, in _gcd_import
2025-10-20T15:55:11.470267549Z [err]    File "<frozen importlib._bootstrap>", line 1178, in _find_and_load
2025-10-20T15:55:11.470271980Z [err]    File "<frozen importlib._bootstrap>", line 1149, in _find_and_load_unlocked
2025-10-20T15:55:11.470275691Z [err]    File "<frozen importlib._bootstrap>", line 690, in _load_unlocked
2025-10-20T15:55:11.470279366Z [err]    File "<frozen importlib._bootstrap_external>", line 940, in exec_module
2025-10-20T15:55:11.470282898Z [err]    File "<frozen importlib._bootstrap>", line 241, in _call_with_frames_removed
2025-10-20T15:55:11.471322351Z [err]                 ^^^^^^^^^^^^^^^^^^^^^^^^^^^^^
2025-10-20T15:55:11.471331573Z [err]    File "/app/.venv/lib/python3.11/site-packages/keras/src/engine/sequential.py", line 466, in from_config
2025-10-20T15:55:11.471338078Z [err]      layer = layer_module.deserialize(
2025-10-20T15:55:11.471344301Z [err]              ^^^^^^^^^^^^^^^^^^^^^^^^^
2025-10-20T15:55:11.471344422Z [err]    File "/app/api.py", line 19, in <module>
2025-10-20T15:55:11.471352245Z [err]      model = keras.models.load_model(model_path)
2025-10-20T15:55:11.471352499Z [err]    File "/app/.venv/lib/python3.11/site-packages/keras/src/layers/serialization.py", line 276, in deserialize
2025-10-20T15:55:11.471358213Z [err]              ^^^^^^^^^^^^^^^^^^^^^^^^^^^^^^^^^^^
2025-10-20T15:55:11.471361650Z [err]      return serialization_lib.deserialize_keras_object(
2025-10-20T15:55:11.471364315Z [err]    File "/app/.venv/lib/python3.11/site-packages/keras/src/saving/saving_api.py", line 254, in load_model
2025-10-20T15:55:11.471368827Z [err]             ^^^^^^^^^^^^^^^^^^^^^^^^^^^^^^^^^^^^^^^^^^^
2025-10-20T15:55:11.471370162Z [err]      return saving_lib.load_model(
2025-10-20T15:55:11.471375372Z [err]             ^^^^^^^^^^^^^^^^^^^^^^
2025-10-20T15:55:11.471380347Z [err]    File "/app/.venv/lib/python3.11/site-packages/keras/src/saving/saving_lib.py", line 281, in load_model
2025-10-20T15:55:11.471385762Z [err]      raise e
2025-10-20T15:55:11.471390820Z [err]    File "/app/.venv/lib/python3.11/site-packages/keras/src/saving/saving_lib.py", line 246, in load_model
2025-10-20T15:55:11.471395332Z [err]      model = deserialize_keras_object(
2025-10-20T15:55:11.471400153Z [err]              ^^^^^^^^^^^^^^^^^^^^^^^^^
2025-10-20T15:55:11.471404990Z [err]    File "/app/.venv/lib/python3.11/site-packages/keras/src/saving/serialization_lib.py", line 728, in deserialize_keras_object
2025-10-20T15:55:11.471409734Z [err]      instance = cls.from_config(inner_config)
2025-10-20T15:55:11.472779791Z [err]    File "/app/.venv/lib/python3.11/site-packages/keras/src/saving/serialization_lib.py", line 609, in deserialize_keras_object
2025-10-20T15:55:11.472791311Z [err]      return deserialize_keras_object(
2025-10-20T15:55:11.472798002Z [err]             ^^^^^^^^^^^^^^^^^^^^^^^^^
2025-10-20T15:55:11.472804664Z [err]    File "/app/.venv/lib/python3.11/site-packages/keras/src/saving/serialization_lib.py", line 728, in deserialize_keras_object
2025-10-20T15:55:11.472810737Z [err]      instance = cls.from_config(inner_config)
2025-10-20T15:55:11.472816313Z [err]                 ^^^^^^^^^^^^^^^^^^^^^^^^^^^^^
2025-10-20T15:55:11.472822907Z [err]    File "/app/.venv/lib/python3.11/site-packages/keras/src/engine/base_layer.py", line 870, in from_config
2025-10-20T15:55:11.472829485Z [err]      raise TypeError(
2025-10-20T15:55:11.472835895Z [err]  TypeError: Error when deserializing class 'InputLayer' using config={'batch_shape': [None, 128, 128, 3], 'dtype': 'float32', 'sparse': False, 'ragged': False, 'name': 'input_layer'}.
2025-10-20T15:55:11.472842807Z [err]
2025-10-20T15:55:11.472852564Z [err]  Exception encountered: Unrecognized keyword arguments: ['batch_shape']
2025-10-20T15:55:11.472858514Z [err]  [2025-10-20 15:55:11 +0000] [2] [INFO] Worker exiting (pid: 2)
2025-10-20T15:55:11.986433466Z [err]  [2025-10-20 15:55:11 +0000] [1] [ERROR] Worker (pid:2) exited with code 3
2025-10-20T15:55:11.986441739Z [err]  [2025-10-20 15:55:11 +0000] [1] [ERROR] Shutting down: Master
2025-10-20T15:55:11.986448373Z [err]  [2025-10-20 15:55:11 +0000] [1] [ERROR] Reason: Worker failed to boot.